[15-Apr-25 13:28:25 - INFO] - lgram.core - Starting Bot...
[15-Apr-25 13:28:25 - INFO] - lgram - Main bot and clone bot management initialized.
[15-Apr-25 13:28:45 - INFO] - lgram.core - Running Deletor 
[15-Apr-25 13:28:45 - INFO] - lgram modules - Successfully imported all modules.
[15-Apr-25 13:28:45 - INFO] - Clone Manager - Restarting all cloned bots...
[15-Apr-25 14:03:22 - INFO] - lgram.core - Starting Bot...
[15-Apr-25 14:03:22 - INFO] - lgram - Main bot and clone bot management initialized.
[15-Apr-25 14:03:38 - INFO] - lgram.core - Running Deletor 
[15-Apr-25 14:03:38 - INFO] - lgram modules - Successfully imported all modules.
[15-Apr-25 14:03:38 - INFO] - Clone Manager - Restarting all cloned bots...
[15-Apr-25 14:08:05 - INFO] - lgram.core - Starting Bot...
[15-Apr-25 14:08:05 - INFO] - lgram - Main bot and clone bot management initialized.
[15-Apr-25 14:08:21 - INFO] - lgram.core - Running Deletor 
[15-Apr-25 14:08:21 - INFO] - lgram modules - Successfully imported all modules.
[15-Apr-25 14:08:21 - INFO] - Clone Manager - Restarting all cloned bots...
[15-Apr-25 19:55:25 - INFO] - lgram.core - Starting Bot...
[15-Apr-25 19:55:25 - INFO] - lgram - Main bot and clone bot management initialized.
[15-Apr-25 19:55:40 - INFO] - lgram.core - Running Deletor 
[15-Apr-25 19:55:40 - INFO] - lgram modules - Successfully imported all modules.
[15-Apr-25 19:55:40 - INFO] - Clone Manager - Restarting all cloned bots...
[15-Apr-25 20:01:36 - INFO] - lgram.core - Starting Bot...
[15-Apr-25 20:01:36 - INFO] - lgram - Main bot and clone bot management initialized.
[15-Apr-25 20:02:03 - INFO] - lgram.core - Running Deletor 
[15-Apr-25 20:02:03 - INFO] - lgram modules - Successfully imported all modules.
[15-Apr-25 20:02:03 - INFO] - Clone Manager - Restarting all cloned bots...
[15-Apr-25 20:02:08 - ERROR] - Clone Manager - Failed token remoked @lgramcloneBot
[15-Apr-25 20:02:17 - INFO] - Clone Manager - Started cloned bot @autoneobot
[15-Apr-25 20:02:21 - ERROR] - Clone Manager - Failed token remoked @lgramcloneBot
[15-Apr-25 20:02:29 - INFO] - Clone Manager - Started cloned bot @dhsjaoamanamaksbot
[15-Apr-25 20:02:38 - INFO] - Clone Manager - Started cloned bot @testsgMegbot
[15-Apr-25 20:02:44 - INFO] - Clone Manager - Started cloned bot @MissIvoryBot
[15-Apr-25 20:02:48 - ERROR] - Clone Manager - Failed token remoked @CtskrBot
[15-Apr-25 20:02:53 - ERROR] - root - Error while cloning bot.
Traceback (most recent call last):
  File "C:\Users\psasw\OneDrive\Desktop\livegram\lgram\__main__.py", line 81, in on_clone
    start_msg = await client.listen(user_id)
                      ^^^^^^^^^^^^^
AttributeError: 'app' object has no attribute 'listen'
[15-Apr-25 20:02:54 - INFO] - Clone Manager - Started cloned bot @DevChatRobot
[15-Apr-25 20:03:02 - INFO] - Clone Manager - Started cloned bot @AXIIVBOT
[15-Apr-25 20:03:06 - ERROR] - Clone Manager - Failed token remoked @rowdybabee_bot
[15-Apr-25 20:03:14 - INFO] - Clone Manager - Started cloned bot @Siniyas_bot
[15-Apr-25 20:03:21 - INFO] - Clone Manager - Started cloned bot @MissAkenoBot
[15-Apr-25 20:03:27 - INFO] - Clone Manager - Started cloned bot @Elsarobot
[15-Apr-25 20:03:30 - ERROR] - Clone Manager - Failed token remoked @nimmi_bot
[15-Apr-25 20:03:36 - INFO] - Clone Manager - Started cloned bot @MissCornBot
[15-Apr-25 20:03:43 - INFO] - Clone Manager - Started cloned bot @asDFgmmhvgfgfsDasdfgfnbmbot
[15-Apr-25 20:03:51 - INFO] - Clone Manager - Started cloned bot @Hykoi09bot
[15-Apr-25 20:03:55 - ERROR] - Clone Manager - Failed token remoked @MissRocketuRaniBot
[15-Apr-25 20:07:31 - ERROR] - root - Error while cloning bot.
Traceback (most recent call last):
  File "C:\Users\psasw\OneDrive\Desktop\livegram\lgram\__main__.py", line 77, in on_clone
    )
  File "C:\Users\psasw\AppData\Local\Packages\PythonSoftwareFoundation.Python.3.12_qbz5n2kfra8p0\LocalCache\local-packages\Python312\site-packages\pyrogram\methods\utilities\start.py", line 58, in start
    is_authorized = await self.connect()
                    ^^^^^^^^^^^^^^^^^^^^
  File "C:\Users\psasw\AppData\Local\Packages\PythonSoftwareFoundation.Python.3.12_qbz5n2kfra8p0\LocalCache\local-packages\Python312\site-packages\pyrogram\methods\auth\connect.py", line 40, in connect
    await self.load_session()
  File "C:\Users\psasw\AppData\Local\Packages\PythonSoftwareFoundation.Python.3.12_qbz5n2kfra8p0\LocalCache\local-packages\Python312\site-packages\pyrogram\client.py", line 616, in load_session
    await self.storage.open()
  File "C:\Users\psasw\AppData\Local\Packages\PythonSoftwareFoundation.Python.3.12_qbz5n2kfra8p0\LocalCache\local-packages\Python312\site-packages\pyrogram\storage\file_storage.py", line 63, in open
    self.update()
  File "C:\Users\psasw\AppData\Local\Packages\PythonSoftwareFoundation.Python.3.12_qbz5n2kfra8p0\LocalCache\local-packages\Python312\site-packages\pyrogram\storage\file_storage.py", line 52, in update
    self.version(version)
  File "C:\Users\psasw\AppData\Local\Packages\PythonSoftwareFoundation.Python.3.12_qbz5n2kfra8p0\LocalCache\local-packages\Python312\site-packages\pyrogram\storage\sqlite_storage.py", line 219, in version
    self.conn.execute(
sqlite3.OperationalError: database is locked
[15-Apr-25 20:07:41 - INFO] - root - Stop signal received (SIGINT). Exiting...
[15-Apr-25 20:07:42 - INFO] - root - Stop signal received (SIGINT). Exiting...
[15-Apr-25 20:09:47 - INFO] - lgram.core - Starting Bot...
[15-Apr-25 20:09:47 - INFO] - lgram - Main bot and clone bot management initialized.
[15-Apr-25 20:09:55 - INFO] - lgram.core - Running Deletor 
[15-Apr-25 20:09:55 - INFO] - lgram modules - Successfully imported all modules.
[15-Apr-25 20:09:55 - INFO] - Clone Manager - Restarting all cloned bots...
[15-Apr-25 20:10:02 - INFO] - Clone Manager - Started cloned bot @ImageGeneratorRoBot
[15-Apr-25 20:10:10 - INFO] - Clone Manager - Started cloned bot @Andipari364bot
[15-Apr-25 20:10:17 - INFO] - Clone Manager - Started cloned bot @AndreaPlaybot
[15-Apr-25 20:10:24 - INFO] - Clone Manager - Started cloned bot @AntispamfedBot
[15-Apr-25 20:10:25 - INFO] - Clone Manager - Started cloned bot @AXIIVBOT
[15-Apr-25 20:10:32 - ERROR] - pyrogram.dispatcher - 'app' object has no attribute 'listeners'
Traceback (most recent call last):
  File "C:\Users\psasw\AppData\Local\Packages\PythonSoftwareFoundation.Python.3.12_qbz5n2kfra8p0\LocalCache\local-packages\Python312\site-packages\pyrogram\dispatcher.py", line 226, in handler_worker
    if await handler.check(self.client, parsed_update):
       ^^^^^^^^^^^^^^^^^^^^^^^^^^^^^^^^^^^^^^^^^^^^^^^
  File "C:\Users\psasw\AppData\Local\Packages\PythonSoftwareFoundation.Python.3.12_qbz5n2kfra8p0\LocalCache\local-packages\Python312\site-packages\pyromod\listen\message_handler.py", line 58, in check
    await self.check_if_has_matching_listener(client, message)
  File "C:\Users\psasw\AppData\Local\Packages\PythonSoftwareFoundation.Python.3.12_qbz5n2kfra8p0\LocalCache\local-packages\Python312\site-packages\pyromod\listen\message_handler.py", line 37, in check_if_has_matching_listener
    listener = client.get_listener_matching_with_data(data, ListenerTypes.MESSAGE)
               ^^^^^^^^^^^^^^^^^^^^^^^^^^^^^^^^^^^^^^^^^^^^^^^^^^^^^^^^^^^^^^^^^^^
  File "C:\Users\psasw\AppData\Local\Packages\PythonSoftwareFoundation.Python.3.12_qbz5n2kfra8p0\LocalCache\local-packages\Python312\site-packages\pyrogram\sync.py", line 53, in async_to_sync_wrap
    coroutine = function(*args, **kwargs)
                ^^^^^^^^^^^^^^^^^^^^^^^^^
  File "C:\Users\psasw\AppData\Local\Packages\PythonSoftwareFoundation.Python.3.12_qbz5n2kfra8p0\LocalCache\local-packages\Python312\site-packages\pyromod\listen\client.py", line 123, in get_listener_matching_with_data
    for listener in self.listeners[listener_type]:
                    ^^^^^^^^^^^^^^
AttributeError: 'app' object has no attribute 'listeners'. Did you mean: 'listen'?
[15-Apr-25 20:10:32 - ERROR] - pyrogram.dispatcher - 'app' object has no attribute 'listeners'
Traceback (most recent call last):
  File "C:\Users\psasw\AppData\Local\Packages\PythonSoftwareFoundation.Python.3.12_qbz5n2kfra8p0\LocalCache\local-packages\Python312\site-packages\pyrogram\dispatcher.py", line 226, in handler_worker
    if await handler.check(self.client, parsed_update):
       ^^^^^^^^^^^^^^^^^^^^^^^^^^^^^^^^^^^^^^^^^^^^^^^
  File "C:\Users\psasw\AppData\Local\Packages\PythonSoftwareFoundation.Python.3.12_qbz5n2kfra8p0\LocalCache\local-packages\Python312\site-packages\pyromod\listen\message_handler.py", line 58, in check
    await self.check_if_has_matching_listener(client, message)
  File "C:\Users\psasw\AppData\Local\Packages\PythonSoftwareFoundation.Python.3.12_qbz5n2kfra8p0\LocalCache\local-packages\Python312\site-packages\pyromod\listen\message_handler.py", line 37, in check_if_has_matching_listener
    listener = client.get_listener_matching_with_data(data, ListenerTypes.MESSAGE)
               ^^^^^^^^^^^^^^^^^^^^^^^^^^^^^^^^^^^^^^^^^^^^^^^^^^^^^^^^^^^^^^^^^^^
  File "C:\Users\psasw\AppData\Local\Packages\PythonSoftwareFoundation.Python.3.12_qbz5n2kfra8p0\LocalCache\local-packages\Python312\site-packages\pyrogram\sync.py", line 53, in async_to_sync_wrap
    coroutine = function(*args, **kwargs)
                ^^^^^^^^^^^^^^^^^^^^^^^^^
  File "C:\Users\psasw\AppData\Local\Packages\PythonSoftwareFoundation.Python.3.12_qbz5n2kfra8p0\LocalCache\local-packages\Python312\site-packages\pyromod\listen\client.py", line 123, in get_listener_matching_with_data
    for listener in self.listeners[listener_type]:
                    ^^^^^^^^^^^^^^
AttributeError: 'app' object has no attribute 'listeners'. Did you mean: 'listen'?
[15-Apr-25 20:10:32 - ERROR] - pyrogram.dispatcher - 'app' object has no attribute 'listeners'
Traceback (most recent call last):
  File "C:\Users\psasw\AppData\Local\Packages\PythonSoftwareFoundation.Python.3.12_qbz5n2kfra8p0\LocalCache\local-packages\Python312\site-packages\pyrogram\dispatcher.py", line 226, in handler_worker
    if await handler.check(self.client, parsed_update):
       ^^^^^^^^^^^^^^^^^^^^^^^^^^^^^^^^^^^^^^^^^^^^^^^
  File "C:\Users\psasw\AppData\Local\Packages\PythonSoftwareFoundation.Python.3.12_qbz5n2kfra8p0\LocalCache\local-packages\Python312\site-packages\pyromod\listen\message_handler.py", line 58, in check
    await self.check_if_has_matching_listener(client, message)
  File "C:\Users\psasw\AppData\Local\Packages\PythonSoftwareFoundation.Python.3.12_qbz5n2kfra8p0\LocalCache\local-packages\Python312\site-packages\pyromod\listen\message_handler.py", line 37, in check_if_has_matching_listener
    listener = client.get_listener_matching_with_data(data, ListenerTypes.MESSAGE)
               ^^^^^^^^^^^^^^^^^^^^^^^^^^^^^^^^^^^^^^^^^^^^^^^^^^^^^^^^^^^^^^^^^^^
  File "C:\Users\psasw\AppData\Local\Packages\PythonSoftwareFoundation.Python.3.12_qbz5n2kfra8p0\LocalCache\local-packages\Python312\site-packages\pyrogram\sync.py", line 53, in async_to_sync_wrap
    coroutine = function(*args, **kwargs)
                ^^^^^^^^^^^^^^^^^^^^^^^^^
  File "C:\Users\psasw\AppData\Local\Packages\PythonSoftwareFoundation.Python.3.12_qbz5n2kfra8p0\LocalCache\local-packages\Python312\site-packages\pyromod\listen\client.py", line 123, in get_listener_matching_with_data
    for listener in self.listeners[listener_type]:
                    ^^^^^^^^^^^^^^
AttributeError: 'app' object has no attribute 'listeners'. Did you mean: 'listen'?
[15-Apr-25 20:12:05 - INFO] - root - Stop signal received (SIGINT). Exiting...
[15-Apr-25 20:12:06 - INFO] - root - Stop signal received (SIGINT). Exiting...
[15-Apr-25 20:12:14 - INFO] - lgram.core - Starting Bot...
[15-Apr-25 20:12:14 - INFO] - lgram - Main bot and clone bot management initialized.
[15-Apr-25 20:12:22 - INFO] - lgram.core - Running Deletor 
[15-Apr-25 20:12:22 - INFO] - lgram modules - Successfully imported all modules.
[15-Apr-25 20:12:22 - INFO] - Clone Manager - Restarting all cloned bots...
[15-Apr-25 20:12:23 - INFO] - Clone Manager - Started cloned bot @ImageGeneratorRoBot
[15-Apr-25 20:12:25 - INFO] - Clone Manager - Started cloned bot @Andipari364bot
[15-Apr-25 20:12:27 - INFO] - Clone Manager - Started cloned bot @AndreaPlaybot
[15-Apr-25 20:12:27 - INFO] - Clone Manager - Started cloned bot @AntispamfedBot
[15-Apr-25 20:12:28 - INFO] - Clone Manager - Started cloned bot @AXIIVBOT
[15-Apr-25 20:22:41 - ERROR] - pyrogram.dispatcher - 'app' object has no attribute 'listeners'
Traceback (most recent call last):
  File "C:\Users\psasw\AppData\Local\Packages\PythonSoftwareFoundation.Python.3.12_qbz5n2kfra8p0\LocalCache\local-packages\Python312\site-packages\pyrogram\dispatcher.py", line 226, in handler_worker
    if await handler.check(self.client, parsed_update):
       ^^^^^^^^^^^^^^^^^^^^^^^^^^^^^^^^^^^^^^^^^^^^^^^
  File "C:\Users\psasw\AppData\Local\Packages\PythonSoftwareFoundation.Python.3.12_qbz5n2kfra8p0\LocalCache\local-packages\Python312\site-packages\pyromod\listen\message_handler.py", line 58, in check
    await self.check_if_has_matching_listener(client, message)
  File "C:\Users\psasw\AppData\Local\Packages\PythonSoftwareFoundation.Python.3.12_qbz5n2kfra8p0\LocalCache\local-packages\Python312\site-packages\pyromod\listen\message_handler.py", line 37, in check_if_has_matching_listener
    listener = client.get_listener_matching_with_data(data, ListenerTypes.MESSAGE)
               ^^^^^^^^^^^^^^^^^^^^^^^^^^^^^^^^^^^^^^^^^^^^^^^^^^^^^^^^^^^^^^^^^^^
  File "C:\Users\psasw\AppData\Local\Packages\PythonSoftwareFoundation.Python.3.12_qbz5n2kfra8p0\LocalCache\local-packages\Python312\site-packages\pyrogram\sync.py", line 53, in async_to_sync_wrap
    coroutine = function(*args, **kwargs)
                ^^^^^^^^^^^^^^^^^^^^^^^^^
  File "C:\Users\psasw\AppData\Local\Packages\PythonSoftwareFoundation.Python.3.12_qbz5n2kfra8p0\LocalCache\local-packages\Python312\site-packages\pyromod\listen\client.py", line 123, in get_listener_matching_with_data
    for listener in self.listeners[listener_type]:
                    ^^^^^^^^^^^^^^
AttributeError: 'app' object has no attribute 'listeners'. Did you mean: 'listen'?
[15-Apr-25 20:22:41 - ERROR] - pyrogram.dispatcher - 'app' object has no attribute 'listeners'
Traceback (most recent call last):
  File "C:\Users\psasw\AppData\Local\Packages\PythonSoftwareFoundation.Python.3.12_qbz5n2kfra8p0\LocalCache\local-packages\Python312\site-packages\pyrogram\dispatcher.py", line 226, in handler_worker
    if await handler.check(self.client, parsed_update):
       ^^^^^^^^^^^^^^^^^^^^^^^^^^^^^^^^^^^^^^^^^^^^^^^
  File "C:\Users\psasw\AppData\Local\Packages\PythonSoftwareFoundation.Python.3.12_qbz5n2kfra8p0\LocalCache\local-packages\Python312\site-packages\pyromod\listen\message_handler.py", line 58, in check
    await self.check_if_has_matching_listener(client, message)
  File "C:\Users\psasw\AppData\Local\Packages\PythonSoftwareFoundation.Python.3.12_qbz5n2kfra8p0\LocalCache\local-packages\Python312\site-packages\pyromod\listen\message_handler.py", line 37, in check_if_has_matching_listener
    listener = client.get_listener_matching_with_data(data, ListenerTypes.MESSAGE)
               ^^^^^^^^^^^^^^^^^^^^^^^^^^^^^^^^^^^^^^^^^^^^^^^^^^^^^^^^^^^^^^^^^^^
  File "C:\Users\psasw\AppData\Local\Packages\PythonSoftwareFoundation.Python.3.12_qbz5n2kfra8p0\LocalCache\local-packages\Python312\site-packages\pyrogram\sync.py", line 53, in async_to_sync_wrap
    coroutine = function(*args, **kwargs)
                ^^^^^^^^^^^^^^^^^^^^^^^^^
  File "C:\Users\psasw\AppData\Local\Packages\PythonSoftwareFoundation.Python.3.12_qbz5n2kfra8p0\LocalCache\local-packages\Python312\site-packages\pyromod\listen\client.py", line 123, in get_listener_matching_with_data
    for listener in self.listeners[listener_type]:
                    ^^^^^^^^^^^^^^
AttributeError: 'app' object has no attribute 'listeners'. Did you mean: 'listen'?
[15-Apr-25 20:22:41 - ERROR] - pyrogram.dispatcher - 'app' object has no attribute 'listeners'
Traceback (most recent call last):
  File "C:\Users\psasw\AppData\Local\Packages\PythonSoftwareFoundation.Python.3.12_qbz5n2kfra8p0\LocalCache\local-packages\Python312\site-packages\pyrogram\dispatcher.py", line 226, in handler_worker
    if await handler.check(self.client, parsed_update):
       ^^^^^^^^^^^^^^^^^^^^^^^^^^^^^^^^^^^^^^^^^^^^^^^
  File "C:\Users\psasw\AppData\Local\Packages\PythonSoftwareFoundation.Python.3.12_qbz5n2kfra8p0\LocalCache\local-packages\Python312\site-packages\pyromod\listen\message_handler.py", line 58, in check
    await self.check_if_has_matching_listener(client, message)
  File "C:\Users\psasw\AppData\Local\Packages\PythonSoftwareFoundation.Python.3.12_qbz5n2kfra8p0\LocalCache\local-packages\Python312\site-packages\pyromod\listen\message_handler.py", line 37, in check_if_has_matching_listener
    listener = client.get_listener_matching_with_data(data, ListenerTypes.MESSAGE)
               ^^^^^^^^^^^^^^^^^^^^^^^^^^^^^^^^^^^^^^^^^^^^^^^^^^^^^^^^^^^^^^^^^^^
  File "C:\Users\psasw\AppData\Local\Packages\PythonSoftwareFoundation.Python.3.12_qbz5n2kfra8p0\LocalCache\local-packages\Python312\site-packages\pyrogram\sync.py", line 53, in async_to_sync_wrap
    coroutine = function(*args, **kwargs)
                ^^^^^^^^^^^^^^^^^^^^^^^^^
  File "C:\Users\psasw\AppData\Local\Packages\PythonSoftwareFoundation.Python.3.12_qbz5n2kfra8p0\LocalCache\local-packages\Python312\site-packages\pyromod\listen\client.py", line 123, in get_listener_matching_with_data
    for listener in self.listeners[listener_type]:
                    ^^^^^^^^^^^^^^
AttributeError: 'app' object has no attribute 'listeners'. Did you mean: 'listen'?
[15-Apr-25 21:16:29 - INFO] - root - Stop signal received (SIGINT). Exiting...
[15-Apr-25 21:16:29 - INFO] - root - Stop signal received (SIGINT). Exiting...
[15-Apr-25 21:16:29 - INFO] - root - Stop signal received (SIGINT). Exiting...
[15-Apr-25 21:16:47 - INFO] - lgram.core - Starting Bot...
[15-Apr-25 21:16:47 - INFO] - lgram - Main bot and clone bot management initialized.
[15-Apr-25 21:16:57 - INFO] - lgram.core - Running Deletor 
[15-Apr-25 21:16:57 - INFO] - lgram modules - Successfully imported all modules.
[15-Apr-25 21:16:57 - INFO] - Clone Manager - Restarting all cloned bots...
[15-Apr-25 21:16:58 - ERROR] - Clone Manager - Error @ImageGeneratorRoBot :cannot import name 'SUPPORT_GROUP' from 'config' (C:\Users\psasw\OneDrive\Desktop\livegram\config.py)
Traceback (most recent call last):
  File "C:\Users\psasw\OneDrive\Desktop\livegram\lgram\__main__.py", line 42, in restart_clones
    await ai.start()
  File "C:\Users\psasw\AppData\Local\Packages\PythonSoftwareFoundation.Python.3.12_qbz5n2kfra8p0\LocalCache\local-packages\Python312\site-packages\pyrogram\methods\utilities\start.py", line 74, in start
    await self.initialize()
  File "C:\Users\psasw\AppData\Local\Packages\PythonSoftwareFoundation.Python.3.12_qbz5n2kfra8p0\LocalCache\local-packages\Python312\site-packages\pyrogram\methods\auth\initialize.py", line 46, in initialize
    self.load_plugins()
  File "C:\Users\psasw\AppData\Local\Packages\PythonSoftwareFoundation.Python.3.12_qbz5n2kfra8p0\LocalCache\local-packages\Python312\site-packages\pyrogram\client.py", line 689, in load_plugins
    module = import_module(module_path)
             ^^^^^^^^^^^^^^^^^^^^^^^^^^
  File "C:\Program Files\WindowsApps\PythonSoftwareFoundation.Python.3.12_3.12.2800.0_x64__qbz5n2kfra8p0\Lib\importlib\__init__.py", line 90, in import_module
    return _bootstrap._gcd_import(name[level:], package, level)
           ^^^^^^^^^^^^^^^^^^^^^^^^^^^^^^^^^^^^^^^^^^^^^^^^^^^^
  File "<frozen importlib._bootstrap>", line 1387, in _gcd_import
  File "<frozen importlib._bootstrap>", line 1360, in _find_and_load
  File "<frozen importlib._bootstrap>", line 1331, in _find_and_load_unlocked
  File "<frozen importlib._bootstrap>", line 935, in _load_unlocked
  File "<frozen importlib._bootstrap_external>", line 999, in exec_module
  File "<frozen importlib._bootstrap>", line 488, in _call_with_frames_removed
  File "C:\Users\psasw\OneDrive\Desktop\livegram\lgram\functionsclone\wetdreams.py", line 4, in <module>
    from config import OWNER_ID, SUPPORT_GROUP
ImportError: cannot import name 'SUPPORT_GROUP' from 'config' (C:\Users\psasw\OneDrive\Desktop\livegram\config.py)
[15-Apr-25 21:17:00 - ERROR] - Clone Manager - Error @Andipari364bot :cannot import name 'SUPPORT_GROUP' from 'config' (C:\Users\psasw\OneDrive\Desktop\livegram\config.py)
Traceback (most recent call last):
  File "C:\Users\psasw\OneDrive\Desktop\livegram\lgram\__main__.py", line 42, in restart_clones
    await ai.start()
  File "C:\Users\psasw\AppData\Local\Packages\PythonSoftwareFoundation.Python.3.12_qbz5n2kfra8p0\LocalCache\local-packages\Python312\site-packages\pyrogram\methods\utilities\start.py", line 74, in start
    await self.initialize()
  File "C:\Users\psasw\AppData\Local\Packages\PythonSoftwareFoundation.Python.3.12_qbz5n2kfra8p0\LocalCache\local-packages\Python312\site-packages\pyrogram\methods\auth\initialize.py", line 46, in initialize
    self.load_plugins()
  File "C:\Users\psasw\AppData\Local\Packages\PythonSoftwareFoundation.Python.3.12_qbz5n2kfra8p0\LocalCache\local-packages\Python312\site-packages\pyrogram\client.py", line 689, in load_plugins
    module = import_module(module_path)
             ^^^^^^^^^^^^^^^^^^^^^^^^^^
  File "C:\Program Files\WindowsApps\PythonSoftwareFoundation.Python.3.12_3.12.2800.0_x64__qbz5n2kfra8p0\Lib\importlib\__init__.py", line 90, in import_module
    return _bootstrap._gcd_import(name[level:], package, level)
           ^^^^^^^^^^^^^^^^^^^^^^^^^^^^^^^^^^^^^^^^^^^^^^^^^^^^
  File "<frozen importlib._bootstrap>", line 1387, in _gcd_import
  File "<frozen importlib._bootstrap>", line 1360, in _find_and_load
  File "<frozen importlib._bootstrap>", line 1331, in _find_and_load_unlocked
  File "<frozen importlib._bootstrap>", line 935, in _load_unlocked
  File "<frozen importlib._bootstrap_external>", line 999, in exec_module
  File "<frozen importlib._bootstrap>", line 488, in _call_with_frames_removed
  File "C:\Users\psasw\OneDrive\Desktop\livegram\lgram\functionsclone\wetdreams.py", line 4, in <module>
    from config import OWNER_ID, SUPPORT_GROUP
ImportError: cannot import name 'SUPPORT_GROUP' from 'config' (C:\Users\psasw\OneDrive\Desktop\livegram\config.py)
[15-Apr-25 21:17:01 - ERROR] - Clone Manager - Error @AndreaPlaybot :cannot import name 'SUPPORT_GROUP' from 'config' (C:\Users\psasw\OneDrive\Desktop\livegram\config.py)
Traceback (most recent call last):
  File "C:\Users\psasw\OneDrive\Desktop\livegram\lgram\__main__.py", line 42, in restart_clones
    await ai.start()
  File "C:\Users\psasw\AppData\Local\Packages\PythonSoftwareFoundation.Python.3.12_qbz5n2kfra8p0\LocalCache\local-packages\Python312\site-packages\pyrogram\methods\utilities\start.py", line 74, in start
    await self.initialize()
  File "C:\Users\psasw\AppData\Local\Packages\PythonSoftwareFoundation.Python.3.12_qbz5n2kfra8p0\LocalCache\local-packages\Python312\site-packages\pyrogram\methods\auth\initialize.py", line 46, in initialize
    self.load_plugins()
  File "C:\Users\psasw\AppData\Local\Packages\PythonSoftwareFoundation.Python.3.12_qbz5n2kfra8p0\LocalCache\local-packages\Python312\site-packages\pyrogram\client.py", line 689, in load_plugins
    module = import_module(module_path)
             ^^^^^^^^^^^^^^^^^^^^^^^^^^
  File "C:\Program Files\WindowsApps\PythonSoftwareFoundation.Python.3.12_3.12.2800.0_x64__qbz5n2kfra8p0\Lib\importlib\__init__.py", line 90, in import_module
    return _bootstrap._gcd_import(name[level:], package, level)
           ^^^^^^^^^^^^^^^^^^^^^^^^^^^^^^^^^^^^^^^^^^^^^^^^^^^^
  File "<frozen importlib._bootstrap>", line 1387, in _gcd_import
  File "<frozen importlib._bootstrap>", line 1360, in _find_and_load
  File "<frozen importlib._bootstrap>", line 1331, in _find_and_load_unlocked
  File "<frozen importlib._bootstrap>", line 935, in _load_unlocked
  File "<frozen importlib._bootstrap_external>", line 999, in exec_module
  File "<frozen importlib._bootstrap>", line 488, in _call_with_frames_removed
  File "C:\Users\psasw\OneDrive\Desktop\livegram\lgram\functionsclone\wetdreams.py", line 4, in <module>
    from config import OWNER_ID, SUPPORT_GROUP
ImportError: cannot import name 'SUPPORT_GROUP' from 'config' (C:\Users\psasw\OneDrive\Desktop\livegram\config.py)
[15-Apr-25 21:17:03 - ERROR] - Clone Manager - Error @AntispamfedBot :cannot import name 'SUPPORT_GROUP' from 'config' (C:\Users\psasw\OneDrive\Desktop\livegram\config.py)
Traceback (most recent call last):
  File "C:\Users\psasw\OneDrive\Desktop\livegram\lgram\__main__.py", line 42, in restart_clones
    await ai.start()
  File "C:\Users\psasw\AppData\Local\Packages\PythonSoftwareFoundation.Python.3.12_qbz5n2kfra8p0\LocalCache\local-packages\Python312\site-packages\pyrogram\methods\utilities\start.py", line 74, in start
    await self.initialize()
  File "C:\Users\psasw\AppData\Local\Packages\PythonSoftwareFoundation.Python.3.12_qbz5n2kfra8p0\LocalCache\local-packages\Python312\site-packages\pyrogram\methods\auth\initialize.py", line 46, in initialize
    self.load_plugins()
  File "C:\Users\psasw\AppData\Local\Packages\PythonSoftwareFoundation.Python.3.12_qbz5n2kfra8p0\LocalCache\local-packages\Python312\site-packages\pyrogram\client.py", line 689, in load_plugins
    module = import_module(module_path)
             ^^^^^^^^^^^^^^^^^^^^^^^^^^
  File "C:\Program Files\WindowsApps\PythonSoftwareFoundation.Python.3.12_3.12.2800.0_x64__qbz5n2kfra8p0\Lib\importlib\__init__.py", line 90, in import_module
    return _bootstrap._gcd_import(name[level:], package, level)
           ^^^^^^^^^^^^^^^^^^^^^^^^^^^^^^^^^^^^^^^^^^^^^^^^^^^^
  File "<frozen importlib._bootstrap>", line 1387, in _gcd_import
  File "<frozen importlib._bootstrap>", line 1360, in _find_and_load
  File "<frozen importlib._bootstrap>", line 1331, in _find_and_load_unlocked
  File "<frozen importlib._bootstrap>", line 935, in _load_unlocked
  File "<frozen importlib._bootstrap_external>", line 999, in exec_module
  File "<frozen importlib._bootstrap>", line 488, in _call_with_frames_removed
  File "C:\Users\psasw\OneDrive\Desktop\livegram\lgram\functionsclone\wetdreams.py", line 4, in <module>
    from config import OWNER_ID, SUPPORT_GROUP
ImportError: cannot import name 'SUPPORT_GROUP' from 'config' (C:\Users\psasw\OneDrive\Desktop\livegram\config.py)
[15-Apr-25 21:17:03 - ERROR] - Clone Manager - Error @AXIIVBOT :cannot import name 'SUPPORT_GROUP' from 'config' (C:\Users\psasw\OneDrive\Desktop\livegram\config.py)
Traceback (most recent call last):
  File "C:\Users\psasw\OneDrive\Desktop\livegram\lgram\__main__.py", line 42, in restart_clones
    await ai.start()
  File "C:\Users\psasw\AppData\Local\Packages\PythonSoftwareFoundation.Python.3.12_qbz5n2kfra8p0\LocalCache\local-packages\Python312\site-packages\pyrogram\methods\utilities\start.py", line 74, in start
    await self.initialize()
  File "C:\Users\psasw\AppData\Local\Packages\PythonSoftwareFoundation.Python.3.12_qbz5n2kfra8p0\LocalCache\local-packages\Python312\site-packages\pyrogram\methods\auth\initialize.py", line 46, in initialize
    self.load_plugins()
  File "C:\Users\psasw\AppData\Local\Packages\PythonSoftwareFoundation.Python.3.12_qbz5n2kfra8p0\LocalCache\local-packages\Python312\site-packages\pyrogram\client.py", line 689, in load_plugins
    module = import_module(module_path)
             ^^^^^^^^^^^^^^^^^^^^^^^^^^
  File "C:\Program Files\WindowsApps\PythonSoftwareFoundation.Python.3.12_3.12.2800.0_x64__qbz5n2kfra8p0\Lib\importlib\__init__.py", line 90, in import_module
    return _bootstrap._gcd_import(name[level:], package, level)
           ^^^^^^^^^^^^^^^^^^^^^^^^^^^^^^^^^^^^^^^^^^^^^^^^^^^^
  File "<frozen importlib._bootstrap>", line 1387, in _gcd_import
  File "<frozen importlib._bootstrap>", line 1360, in _find_and_load
  File "<frozen importlib._bootstrap>", line 1331, in _find_and_load_unlocked
  File "<frozen importlib._bootstrap>", line 935, in _load_unlocked
  File "<frozen importlib._bootstrap_external>", line 999, in exec_module
  File "<frozen importlib._bootstrap>", line 488, in _call_with_frames_removed
  File "C:\Users\psasw\OneDrive\Desktop\livegram\lgram\functionsclone\wetdreams.py", line 4, in <module>
    from config import OWNER_ID, SUPPORT_GROUP
ImportError: cannot import name 'SUPPORT_GROUP' from 'config' (C:\Users\psasw\OneDrive\Desktop\livegram\config.py)
[15-Apr-25 21:18:00 - INFO] - root - Stop signal received (SIGINT). Exiting...
[15-Apr-25 21:18:16 - INFO] - lgram.core - Starting Bot...
[15-Apr-25 21:18:16 - INFO] - lgram - Main bot and clone bot management initialized.
[15-Apr-25 21:18:26 - INFO] - lgram.core - Running Deletor 
[15-Apr-25 21:18:26 - INFO] - lgram modules - Successfully imported all modules.
[15-Apr-25 21:18:26 - INFO] - Clone Manager - Restarting all cloned bots...
[15-Apr-25 21:18:28 - ERROR] - Clone Manager - Error @ImageGeneratorRoBot :name 'Bot' is not defined
Traceback (most recent call last):
  File "C:\Users\psasw\OneDrive\Desktop\livegram\lgram\__main__.py", line 42, in restart_clones
    await ai.start()
  File "C:\Users\psasw\AppData\Local\Packages\PythonSoftwareFoundation.Python.3.12_qbz5n2kfra8p0\LocalCache\local-packages\Python312\site-packages\pyrogram\methods\utilities\start.py", line 74, in start
    await self.initialize()
  File "C:\Users\psasw\AppData\Local\Packages\PythonSoftwareFoundation.Python.3.12_qbz5n2kfra8p0\LocalCache\local-packages\Python312\site-packages\pyrogram\methods\auth\initialize.py", line 46, in initialize
    self.load_plugins()
  File "C:\Users\psasw\AppData\Local\Packages\PythonSoftwareFoundation.Python.3.12_qbz5n2kfra8p0\LocalCache\local-packages\Python312\site-packages\pyrogram\client.py", line 689, in load_plugins
    module = import_module(module_path)
             ^^^^^^^^^^^^^^^^^^^^^^^^^^
  File "C:\Program Files\WindowsApps\PythonSoftwareFoundation.Python.3.12_3.12.2800.0_x64__qbz5n2kfra8p0\Lib\importlib\__init__.py", line 90, in import_module
    return _bootstrap._gcd_import(name[level:], package, level)
           ^^^^^^^^^^^^^^^^^^^^^^^^^^^^^^^^^^^^^^^^^^^^^^^^^^^^
  File "<frozen importlib._bootstrap>", line 1387, in _gcd_import
  File "<frozen importlib._bootstrap>", line 1360, in _find_and_load
  File "<frozen importlib._bootstrap>", line 1331, in _find_and_load_unlocked
  File "<frozen importlib._bootstrap>", line 935, in _load_unlocked
  File "<frozen importlib._bootstrap_external>", line 999, in exec_module
  File "<frozen importlib._bootstrap>", line 488, in _call_with_frames_removed
  File "C:\Users\psasw\OneDrive\Desktop\livegram\lgram\functionsclone\wetdreams.py", line 25, in <module>
    async def cancel_broadcast(client: Bot, message: Message):
                                       ^^^
NameError: name 'Bot' is not defined
[15-Apr-25 21:18:30 - ERROR] - Clone Manager - Error @Andipari364bot :name 'Bot' is not defined
Traceback (most recent call last):
  File "C:\Users\psasw\OneDrive\Desktop\livegram\lgram\__main__.py", line 42, in restart_clones
    await ai.start()
  File "C:\Users\psasw\AppData\Local\Packages\PythonSoftwareFoundation.Python.3.12_qbz5n2kfra8p0\LocalCache\local-packages\Python312\site-packages\pyrogram\methods\utilities\start.py", line 74, in start
    await self.initialize()
  File "C:\Users\psasw\AppData\Local\Packages\PythonSoftwareFoundation.Python.3.12_qbz5n2kfra8p0\LocalCache\local-packages\Python312\site-packages\pyrogram\methods\auth\initialize.py", line 46, in initialize
    self.load_plugins()
  File "C:\Users\psasw\AppData\Local\Packages\PythonSoftwareFoundation.Python.3.12_qbz5n2kfra8p0\LocalCache\local-packages\Python312\site-packages\pyrogram\client.py", line 689, in load_plugins
    module = import_module(module_path)
             ^^^^^^^^^^^^^^^^^^^^^^^^^^
  File "C:\Program Files\WindowsApps\PythonSoftwareFoundation.Python.3.12_3.12.2800.0_x64__qbz5n2kfra8p0\Lib\importlib\__init__.py", line 90, in import_module
    return _bootstrap._gcd_import(name[level:], package, level)
           ^^^^^^^^^^^^^^^^^^^^^^^^^^^^^^^^^^^^^^^^^^^^^^^^^^^^
  File "<frozen importlib._bootstrap>", line 1387, in _gcd_import
  File "<frozen importlib._bootstrap>", line 1360, in _find_and_load
  File "<frozen importlib._bootstrap>", line 1331, in _find_and_load_unlocked
  File "<frozen importlib._bootstrap>", line 935, in _load_unlocked
  File "<frozen importlib._bootstrap_external>", line 999, in exec_module
  File "<frozen importlib._bootstrap>", line 488, in _call_with_frames_removed
  File "C:\Users\psasw\OneDrive\Desktop\livegram\lgram\functionsclone\wetdreams.py", line 25, in <module>
    async def cancel_broadcast(client: Bot, message: Message):
                                       ^^^
NameError: name 'Bot' is not defined
[15-Apr-25 21:18:32 - ERROR] - Clone Manager - Error @AndreaPlaybot :name 'Bot' is not defined
Traceback (most recent call last):
  File "C:\Users\psasw\OneDrive\Desktop\livegram\lgram\__main__.py", line 42, in restart_clones
    await ai.start()
  File "C:\Users\psasw\AppData\Local\Packages\PythonSoftwareFoundation.Python.3.12_qbz5n2kfra8p0\LocalCache\local-packages\Python312\site-packages\pyrogram\methods\utilities\start.py", line 74, in start
    await self.initialize()
  File "C:\Users\psasw\AppData\Local\Packages\PythonSoftwareFoundation.Python.3.12_qbz5n2kfra8p0\LocalCache\local-packages\Python312\site-packages\pyrogram\methods\auth\initialize.py", line 46, in initialize
    self.load_plugins()
  File "C:\Users\psasw\AppData\Local\Packages\PythonSoftwareFoundation.Python.3.12_qbz5n2kfra8p0\LocalCache\local-packages\Python312\site-packages\pyrogram\client.py", line 689, in load_plugins
    module = import_module(module_path)
             ^^^^^^^^^^^^^^^^^^^^^^^^^^
  File "C:\Program Files\WindowsApps\PythonSoftwareFoundation.Python.3.12_3.12.2800.0_x64__qbz5n2kfra8p0\Lib\importlib\__init__.py", line 90, in import_module
    return _bootstrap._gcd_import(name[level:], package, level)
           ^^^^^^^^^^^^^^^^^^^^^^^^^^^^^^^^^^^^^^^^^^^^^^^^^^^^
  File "<frozen importlib._bootstrap>", line 1387, in _gcd_import
  File "<frozen importlib._bootstrap>", line 1360, in _find_and_load
  File "<frozen importlib._bootstrap>", line 1331, in _find_and_load_unlocked
  File "<frozen importlib._bootstrap>", line 935, in _load_unlocked
  File "<frozen importlib._bootstrap_external>", line 999, in exec_module
  File "<frozen importlib._bootstrap>", line 488, in _call_with_frames_removed
  File "C:\Users\psasw\OneDrive\Desktop\livegram\lgram\functionsclone\wetdreams.py", line 25, in <module>
    async def cancel_broadcast(client: Bot, message: Message):
                                       ^^^
NameError: name 'Bot' is not defined
[15-Apr-25 21:18:34 - ERROR] - Clone Manager - Error @AntispamfedBot :name 'Bot' is not defined
Traceback (most recent call last):
  File "C:\Users\psasw\OneDrive\Desktop\livegram\lgram\__main__.py", line 42, in restart_clones
    await ai.start()
  File "C:\Users\psasw\AppData\Local\Packages\PythonSoftwareFoundation.Python.3.12_qbz5n2kfra8p0\LocalCache\local-packages\Python312\site-packages\pyrogram\methods\utilities\start.py", line 74, in start
    await self.initialize()
  File "C:\Users\psasw\AppData\Local\Packages\PythonSoftwareFoundation.Python.3.12_qbz5n2kfra8p0\LocalCache\local-packages\Python312\site-packages\pyrogram\methods\auth\initialize.py", line 46, in initialize
    self.load_plugins()
  File "C:\Users\psasw\AppData\Local\Packages\PythonSoftwareFoundation.Python.3.12_qbz5n2kfra8p0\LocalCache\local-packages\Python312\site-packages\pyrogram\client.py", line 689, in load_plugins
    module = import_module(module_path)
             ^^^^^^^^^^^^^^^^^^^^^^^^^^
  File "C:\Program Files\WindowsApps\PythonSoftwareFoundation.Python.3.12_3.12.2800.0_x64__qbz5n2kfra8p0\Lib\importlib\__init__.py", line 90, in import_module
    return _bootstrap._gcd_import(name[level:], package, level)
           ^^^^^^^^^^^^^^^^^^^^^^^^^^^^^^^^^^^^^^^^^^^^^^^^^^^^
  File "<frozen importlib._bootstrap>", line 1387, in _gcd_import
  File "<frozen importlib._bootstrap>", line 1360, in _find_and_load
  File "<frozen importlib._bootstrap>", line 1331, in _find_and_load_unlocked
  File "<frozen importlib._bootstrap>", line 935, in _load_unlocked
  File "<frozen importlib._bootstrap_external>", line 999, in exec_module
  File "<frozen importlib._bootstrap>", line 488, in _call_with_frames_removed
  File "C:\Users\psasw\OneDrive\Desktop\livegram\lgram\functionsclone\wetdreams.py", line 25, in <module>
    async def cancel_broadcast(client: Bot, message: Message):
                                       ^^^
NameError: name 'Bot' is not defined
[15-Apr-25 21:18:35 - ERROR] - Clone Manager - Error @AXIIVBOT :name 'Bot' is not defined
Traceback (most recent call last):
  File "C:\Users\psasw\OneDrive\Desktop\livegram\lgram\__main__.py", line 42, in restart_clones
    await ai.start()
  File "C:\Users\psasw\AppData\Local\Packages\PythonSoftwareFoundation.Python.3.12_qbz5n2kfra8p0\LocalCache\local-packages\Python312\site-packages\pyrogram\methods\utilities\start.py", line 74, in start
    await self.initialize()
  File "C:\Users\psasw\AppData\Local\Packages\PythonSoftwareFoundation.Python.3.12_qbz5n2kfra8p0\LocalCache\local-packages\Python312\site-packages\pyrogram\methods\auth\initialize.py", line 46, in initialize
    self.load_plugins()
  File "C:\Users\psasw\AppData\Local\Packages\PythonSoftwareFoundation.Python.3.12_qbz5n2kfra8p0\LocalCache\local-packages\Python312\site-packages\pyrogram\client.py", line 689, in load_plugins
    module = import_module(module_path)
             ^^^^^^^^^^^^^^^^^^^^^^^^^^
  File "C:\Program Files\WindowsApps\PythonSoftwareFoundation.Python.3.12_3.12.2800.0_x64__qbz5n2kfra8p0\Lib\importlib\__init__.py", line 90, in import_module
    return _bootstrap._gcd_import(name[level:], package, level)
           ^^^^^^^^^^^^^^^^^^^^^^^^^^^^^^^^^^^^^^^^^^^^^^^^^^^^
  File "<frozen importlib._bootstrap>", line 1387, in _gcd_import
  File "<frozen importlib._bootstrap>", line 1360, in _find_and_load
  File "<frozen importlib._bootstrap>", line 1331, in _find_and_load_unlocked
  File "<frozen importlib._bootstrap>", line 935, in _load_unlocked
  File "<frozen importlib._bootstrap_external>", line 999, in exec_module
  File "<frozen importlib._bootstrap>", line 488, in _call_with_frames_removed
  File "C:\Users\psasw\OneDrive\Desktop\livegram\lgram\functionsclone\wetdreams.py", line 25, in <module>
    async def cancel_broadcast(client: Bot, message: Message):
                                       ^^^
NameError: name 'Bot' is not defined
[15-Apr-25 21:19:56 - ERROR] - root - Error while cloning bot.
Traceback (most recent call last):
  File "C:\Users\psasw\OneDrive\Desktop\livegram\lgram\__main__.py", line 83, in on_clone
    await ai.start()
  File "C:\Users\psasw\AppData\Local\Packages\PythonSoftwareFoundation.Python.3.12_qbz5n2kfra8p0\LocalCache\local-packages\Python312\site-packages\pyrogram\methods\utilities\start.py", line 74, in start
    await self.initialize()
  File "C:\Users\psasw\AppData\Local\Packages\PythonSoftwareFoundation.Python.3.12_qbz5n2kfra8p0\LocalCache\local-packages\Python312\site-packages\pyrogram\methods\auth\initialize.py", line 46, in initialize
    self.load_plugins()
  File "C:\Users\psasw\AppData\Local\Packages\PythonSoftwareFoundation.Python.3.12_qbz5n2kfra8p0\LocalCache\local-packages\Python312\site-packages\pyrogram\client.py", line 689, in load_plugins
    module = import_module(module_path)
             ^^^^^^^^^^^^^^^^^^^^^^^^^^
  File "C:\Program Files\WindowsApps\PythonSoftwareFoundation.Python.3.12_3.12.2800.0_x64__qbz5n2kfra8p0\Lib\importlib\__init__.py", line 90, in import_module
    return _bootstrap._gcd_import(name[level:], package, level)
           ^^^^^^^^^^^^^^^^^^^^^^^^^^^^^^^^^^^^^^^^^^^^^^^^^^^^
  File "<frozen importlib._bootstrap>", line 1387, in _gcd_import
  File "<frozen importlib._bootstrap>", line 1360, in _find_and_load
  File "<frozen importlib._bootstrap>", line 1331, in _find_and_load_unlocked
  File "<frozen importlib._bootstrap>", line 935, in _load_unlocked
  File "<frozen importlib._bootstrap_external>", line 999, in exec_module
  File "<frozen importlib._bootstrap>", line 488, in _call_with_frames_removed
  File "C:\Users\psasw\OneDrive\Desktop\livegram\lgram\functionsclone\wetdreams.py", line 25, in <module>
    async def cancel_broadcast(client: Bot, message: Message):
                                       ^^^
NameError: name 'Bot' is not defined
[15-Apr-25 21:21:21 - INFO] - root - Stop signal received (SIGINT). Exiting...
[15-Apr-25 21:21:21 - INFO] - root - Stop signal received (SIGINT). Exiting...
[15-Apr-25 21:21:35 - INFO] - lgram.core - Starting Bot...
[15-Apr-25 21:21:35 - INFO] - lgram - Main bot and clone bot management initialized.
[15-Apr-25 21:21:45 - INFO] - lgram.core - Running Deletor 
[15-Apr-25 21:21:45 - INFO] - lgram modules - Successfully imported all modules.
[15-Apr-25 21:21:45 - INFO] - Clone Manager - Restarting all cloned bots...
[15-Apr-25 21:21:46 - INFO] - Clone Manager - Started cloned bot @ImageGeneratorRoBot
[15-Apr-25 21:21:47 - INFO] - Clone Manager - Started cloned bot @Andipari364bot
[15-Apr-25 21:21:47 - INFO] - Clone Manager - Started cloned bot @AndreaPlaybot
[15-Apr-25 21:21:48 - INFO] - Clone Manager - Started cloned bot @AntispamfedBot
[15-Apr-25 21:21:50 - INFO] - Clone Manager - Started cloned bot @AXIIVBOT
[15-Apr-25 21:23:20 - INFO] - root - Stop signal received (SIGINT). Exiting...
[15-Apr-25 21:23:21 - INFO] - root - Stop signal received (SIGINT). Exiting...
[15-Apr-25 21:23:31 - INFO] - lgram.core - Starting Bot...
[15-Apr-25 21:23:31 - INFO] - lgram - Main bot and clone bot management initialized.
[15-Apr-25 21:23:39 - INFO] - lgram.core - Running Deletor 
[15-Apr-25 21:23:39 - INFO] - lgram modules - Successfully imported all modules.
[15-Apr-25 21:23:39 - INFO] - Clone Manager - Restarting all cloned bots...
[15-Apr-25 21:23:41 - INFO] - Clone Manager - Started cloned bot @ImageGeneratorRoBot
[15-Apr-25 21:23:42 - INFO] - Clone Manager - Started cloned bot @Andipari364bot
[15-Apr-25 21:23:43 - INFO] - Clone Manager - Started cloned bot @AndreaPlaybot
[15-Apr-25 21:23:44 - INFO] - Clone Manager - Started cloned bot @AntispamfedBot
[15-Apr-25 21:23:45 - INFO] - Clone Manager - Started cloned bot @AXIIVBOT
[15-Apr-25 21:23:46 - INFO] - Clone Manager - Started cloned bot @Elsarobot
[16-Apr-25 12:29:54 - INFO] - lgram.core - Starting Bot...
[16-Apr-25 12:29:54 - INFO] - lgram - Main bot and clone bot management initialized.
[16-Apr-25 12:30:03 - INFO] - lgram.core - Running Deletor 
[16-Apr-25 12:30:03 - INFO] - lgram modules - Successfully imported all modules.
[16-Apr-25 12:30:03 - INFO] - Clone Manager - Restarting all cloned bots...
[16-Apr-25 12:30:04 - INFO] - Clone Manager - Started cloned bot @ImageGeneratorRoBot
[16-Apr-25 12:30:05 - INFO] - Clone Manager - Started cloned bot @Andipari364bot
[16-Apr-25 12:30:06 - INFO] - Clone Manager - Started cloned bot @AndreaPlaybot
[16-Apr-25 12:30:07 - INFO] - Clone Manager - Started cloned bot @AntispamfedBot
[16-Apr-25 12:30:07 - INFO] - Clone Manager - Started cloned bot @AXIIVBOT
[16-Apr-25 12:30:08 - INFO] - Clone Manager - Started cloned bot @Elsarobot
[16-Apr-25 12:36:16 - INFO] - root - Stop signal received (SIGINT). Exiting...
[16-Apr-25 12:36:16 - INFO] - root - Stop signal received (SIGINT). Exiting...
[16-Apr-25 12:36:23 - INFO] - lgram.core - Starting Bot...
[16-Apr-25 12:36:23 - INFO] - lgram - Main bot and clone bot management initialized.
[16-Apr-25 12:36:31 - INFO] - lgram.core - Running Deletor 
[16-Apr-25 12:36:31 - INFO] - lgram modules - Successfully imported all modules.
[16-Apr-25 12:36:31 - INFO] - Clone Manager - Restarting all cloned bots...
[16-Apr-25 12:36:32 - INFO] - Clone Manager - Started cloned bot @ImageGeneratorRoBot
[16-Apr-25 12:36:33 - INFO] - Clone Manager - Started cloned bot @Andipari364bot
[16-Apr-25 12:36:34 - INFO] - Clone Manager - Started cloned bot @AndreaPlaybot
[16-Apr-25 12:36:35 - INFO] - Clone Manager - Started cloned bot @AntispamfedBot
[16-Apr-25 12:36:36 - INFO] - Clone Manager - Started cloned bot @AXIIVBOT
[16-Apr-25 12:36:37 - INFO] - Clone Manager - Started cloned bot @Elsarobot
[16-Apr-25 12:36:45 - INFO] - Clone Manager - Started cloned bot @QuizPlayBot
[16-Apr-25 12:40:51 - INFO] - root - Stop signal received (SIGINT). Exiting...
[16-Apr-25 12:40:52 - INFO] - root - Stop signal received (SIGINT). Exiting...
[16-Apr-25 12:40:52 - INFO] - root - Stop signal received (SIGINT). Exiting...
[16-Apr-25 12:41:09 - INFO] - lgram.core - Starting Bot...
[16-Apr-25 12:41:09 - INFO] - lgram - Main bot and clone bot management initialized.
[16-Apr-25 12:41:17 - INFO] - lgram.core - Running Deletor 
[16-Apr-25 12:41:17 - INFO] - lgram modules - Successfully imported all modules.
[16-Apr-25 12:41:17 - INFO] - Clone Manager - Restarting all cloned bots...
[16-Apr-25 12:41:19 - INFO] - Clone Manager - Started cloned bot @ImageGeneratorRoBot
[16-Apr-25 12:41:21 - INFO] - Clone Manager - Started cloned bot @Andipari364bot
[16-Apr-25 12:41:21 - INFO] - Clone Manager - Started cloned bot @AndreaPlaybot
[16-Apr-25 12:41:22 - INFO] - Clone Manager - Started cloned bot @AntispamfedBot
[16-Apr-25 12:41:23 - INFO] - Clone Manager - Started cloned bot @AXIIVBOT
[16-Apr-25 12:41:24 - INFO] - Clone Manager - Started cloned bot @Elsarobot
[16-Apr-25 12:41:25 - INFO] - Clone Manager - Started cloned bot @QuizPlayBot
[16-Apr-25 12:41:32 - INFO] - Clone Manager - Started cloned bot @Savealbot
[16-Apr-25 12:45:06 - INFO] - root - Stop signal received (SIGINT). Exiting...
[16-Apr-25 12:45:16 - INFO] - lgram.core - Starting Bot...
[16-Apr-25 12:45:16 - INFO] - lgram - Main bot and clone bot management initialized.
[16-Apr-25 12:45:24 - INFO] - lgram.core - Running Deletor 
[16-Apr-25 12:45:24 - INFO] - lgram modules - Successfully imported all modules.
[16-Apr-25 12:45:24 - INFO] - Clone Manager - Restarting all cloned bots...
[16-Apr-25 12:45:26 - INFO] - Clone Manager - Started cloned bot @ImageGeneratorRoBot
[16-Apr-25 12:45:26 - INFO] - Clone Manager - Started cloned bot @Andipari364bot
[16-Apr-25 12:45:27 - INFO] - Clone Manager - Started cloned bot @AndreaPlaybot
[16-Apr-25 12:45:28 - INFO] - Clone Manager - Started cloned bot @AntispamfedBot
[16-Apr-25 12:45:29 - INFO] - Clone Manager - Started cloned bot @AXIIVBOT
[16-Apr-25 12:45:30 - INFO] - Clone Manager - Started cloned bot @Elsarobot
[16-Apr-25 12:45:31 - INFO] - Clone Manager - Started cloned bot @QuizPlayBot
[16-Apr-25 12:45:32 - INFO] - Clone Manager - Started cloned bot @Savealbot
[16-Apr-25 12:54:07 - INFO] - root - Stop signal received (SIGINT). Exiting...
[16-Apr-25 12:54:15 - INFO] - lgram.core - Starting Bot...
[16-Apr-25 12:54:15 - INFO] - lgram - Main bot and clone bot management initialized.
[16-Apr-25 12:54:24 - INFO] - lgram.core - Running Deletor 
[16-Apr-25 12:54:24 - INFO] - lgram modules - Successfully imported all modules.
[16-Apr-25 12:54:24 - INFO] - Clone Manager - Restarting all cloned bots...
[16-Apr-25 12:54:26 - INFO] - Clone Manager - Started cloned bot @ImageGeneratorRoBot
[16-Apr-25 12:54:27 - INFO] - Clone Manager - Started cloned bot @Andipari364bot
[16-Apr-25 12:54:28 - INFO] - Clone Manager - Started cloned bot @AndreaPlaybot
[16-Apr-25 12:54:29 - INFO] - Clone Manager - Started cloned bot @AntispamfedBot
[16-Apr-25 12:54:30 - INFO] - Clone Manager - Started cloned bot @AXIIVBOT
[16-Apr-25 12:54:30 - INFO] - Clone Manager - Started cloned bot @Elsarobot
[16-Apr-25 12:54:32 - INFO] - Clone Manager - Started cloned bot @QuizPlayBot
[16-Apr-25 12:54:32 - INFO] - Clone Manager - Started cloned bot @Savealbot
[16-Apr-25 12:55:34 - INFO] - root - Stop signal received (SIGINT). Exiting...
[16-Apr-25 12:55:35 - INFO] - root - Stop signal received (SIGINT). Exiting...
[16-Apr-25 12:55:35 - INFO] - root - Stop signal received (SIGINT). Exiting...
[16-Apr-25 12:55:47 - INFO] - lgram.core - Starting Bot...
[16-Apr-25 12:55:47 - INFO] - lgram - Main bot and clone bot management initialized.
[16-Apr-25 12:55:55 - INFO] - lgram.core - Running Deletor 
[16-Apr-25 12:55:55 - INFO] - lgram modules - Successfully imported all modules.
[16-Apr-25 12:55:55 - INFO] - Clone Manager - Restarting all cloned bots...
[16-Apr-25 12:55:56 - INFO] - Clone Manager - Started cloned bot @ImageGeneratorRoBot
[16-Apr-25 12:55:57 - INFO] - Clone Manager - Started cloned bot @Andipari364bot
[16-Apr-25 12:55:58 - INFO] - Clone Manager - Started cloned bot @AndreaPlaybot
[16-Apr-25 12:55:59 - INFO] - Clone Manager - Started cloned bot @AntispamfedBot
[16-Apr-25 12:56:00 - INFO] - Clone Manager - Started cloned bot @AXIIVBOT
[16-Apr-25 12:56:01 - INFO] - Clone Manager - Started cloned bot @Elsarobot
[16-Apr-25 12:56:01 - INFO] - Clone Manager - Started cloned bot @QuizPlayBot
[16-Apr-25 12:56:02 - INFO] - Clone Manager - Started cloned bot @Savealbot
[16-Apr-25 13:29:32 - WARNING] - asyncio - socket.send() raised exception.
[16-Apr-25 13:29:32 - WARNING] - asyncio - socket.send() raised exception.
[16-Apr-25 13:29:32 - WARNING] - asyncio - socket.send() raised exception.
[16-Apr-25 13:29:32 - WARNING] - asyncio - socket.send() raised exception.
[16-Apr-25 13:29:32 - WARNING] - asyncio - socket.send() raised exception.
[16-Apr-25 13:29:32 - WARNING] - asyncio - socket.send() raised exception.
[16-Apr-25 13:30:17 - WARNING] - asyncio - socket.send() raised exception.
[16-Apr-25 13:30:17 - WARNING] - asyncio - socket.send() raised exception.
[16-Apr-25 13:30:17 - WARNING] - asyncio - socket.send() raised exception.
[16-Apr-25 13:30:17 - WARNING] - asyncio - socket.send() raised exception.
[16-Apr-25 13:30:17 - WARNING] - asyncio - socket.send() raised exception.
[16-Apr-25 13:30:17 - WARNING] - asyncio - socket.send() raised exception.
[16-Apr-25 13:30:17 - WARNING] - asyncio - socket.send() raised exception.
[16-Apr-25 13:30:18 - WARNING] - asyncio - socket.send() raised exception.
[16-Apr-25 13:30:18 - WARNING] - asyncio - socket.send() raised exception.
[16-Apr-25 17:03:41 - INFO] - lgram.core - Starting Bot...
[16-Apr-25 17:03:41 - INFO] - lgram - Main bot and clone bot management initialized.
[16-Apr-25 17:03:53 - INFO] - lgram.core - Running Deletor 
[16-Apr-25 17:03:53 - INFO] - lgram modules - Successfully imported all modules.
[16-Apr-25 17:03:53 - INFO] - Clone Manager - Restarting all cloned bots...
[16-Apr-25 17:03:57 - INFO] - Clone Manager - Started cloned bot @ImageGeneratorRoBot
[16-Apr-25 17:03:58 - INFO] - Clone Manager - Started cloned bot @Andipari364bot
[16-Apr-25 17:03:59 - INFO] - Clone Manager - Started cloned bot @AndreaPlaybot
[16-Apr-25 17:04:00 - INFO] - Clone Manager - Started cloned bot @AntispamfedBot
[16-Apr-25 17:04:01 - INFO] - Clone Manager - Started cloned bot @AXIIVBOT
[16-Apr-25 17:04:02 - INFO] - Clone Manager - Started cloned bot @Elsarobot
[16-Apr-25 17:04:03 - INFO] - Clone Manager - Started cloned bot @QuizPlayBot
[16-Apr-25 17:04:04 - INFO] - Clone Manager - Started cloned bot @Savealbot
[16-Apr-25 17:19:48 - INFO] - root - Stop signal received (SIGINT). Exiting...
[16-Apr-25 17:19:49 - INFO] - root - Stop signal received (SIGINT). Exiting...
[16-Apr-25 17:19:57 - INFO] - lgram.core - Starting Bot...
[16-Apr-25 17:19:57 - INFO] - lgram - Main bot and clone bot management initialized.
[16-Apr-25 17:20:05 - INFO] - lgram.core - Running Deletor 
[16-Apr-25 17:20:05 - INFO] - lgram modules - Successfully imported all modules.
[16-Apr-25 17:20:05 - INFO] - Clone Manager - Restarting all cloned bots...
[16-Apr-25 17:20:06 - INFO] - Clone Manager - Started cloned bot @ImageGeneratorRoBot
[16-Apr-25 17:20:07 - INFO] - Clone Manager - Started cloned bot @Andipari364bot
[16-Apr-25 17:20:08 - INFO] - Clone Manager - Started cloned bot @AndreaPlaybot
[16-Apr-25 17:20:09 - INFO] - Clone Manager - Started cloned bot @AntispamfedBot
[16-Apr-25 17:20:09 - INFO] - Clone Manager - Started cloned bot @AXIIVBOT
[16-Apr-25 17:20:11 - INFO] - Clone Manager - Started cloned bot @Elsarobot
[16-Apr-25 17:20:11 - INFO] - Clone Manager - Started cloned bot @QuizPlayBot
[16-Apr-25 17:20:12 - INFO] - Clone Manager - Started cloned bot @Savealbot
[16-Apr-25 17:22:59 - INFO] - root - Stop signal received (SIGINT). Exiting...
[16-Apr-25 17:22:59 - INFO] - root - Stop signal received (SIGINT). Exiting...
[16-Apr-25 17:23:13 - INFO] - lgram.core - Starting Bot...
[16-Apr-25 17:23:13 - INFO] - lgram - Main bot and clone bot management initialized.
[16-Apr-25 17:23:22 - INFO] - lgram.core - Running Deletor 
[16-Apr-25 17:23:22 - INFO] - lgram modules - Successfully imported all modules.
[16-Apr-25 17:23:22 - INFO] - Clone Manager - Restarting all cloned bots...
[16-Apr-25 17:23:24 - INFO] - Clone Manager - Started cloned bot @ImageGeneratorRoBot
[16-Apr-25 17:23:25 - INFO] - Clone Manager - Started cloned bot @Andipari364bot
[16-Apr-25 17:23:25 - INFO] - Clone Manager - Started cloned bot @AndreaPlaybot
[16-Apr-25 17:23:26 - INFO] - Clone Manager - Started cloned bot @AntispamfedBot
[16-Apr-25 17:23:28 - INFO] - Clone Manager - Started cloned bot @AXIIVBOT
[16-Apr-25 17:23:29 - INFO] - Clone Manager - Started cloned bot @Elsarobot
[16-Apr-25 17:23:29 - INFO] - Clone Manager - Started cloned bot @QuizPlayBot
[16-Apr-25 17:23:31 - INFO] - Clone Manager - Started cloned bot @Savealbot
[16-Apr-25 17:44:09 - INFO] - root - Stop signal received (SIGINT). Exiting...
[16-Apr-25 17:44:10 - INFO] - root - Stop signal received (SIGINT). Exiting...
[16-Apr-25 17:44:21 - INFO] - lgram.core - Starting Bot...
[16-Apr-25 17:44:21 - INFO] - lgram - Main bot and clone bot management initialized.
[16-Apr-25 17:44:29 - INFO] - lgram.core - Running Deletor 
[16-Apr-25 17:44:29 - INFO] - lgram modules - Successfully imported all modules.
[16-Apr-25 17:44:29 - INFO] - Clone Manager - Restarting all cloned bots...
[16-Apr-25 17:44:31 - INFO] - Clone Manager - Started cloned bot @ImageGeneratorRoBot
[16-Apr-25 17:44:33 - INFO] - Clone Manager - Started cloned bot @Andipari364bot
[16-Apr-25 17:44:34 - INFO] - Clone Manager - Started cloned bot @AndreaPlaybot
[16-Apr-25 17:44:35 - INFO] - Clone Manager - Started cloned bot @AntispamfedBot
[16-Apr-25 17:44:36 - INFO] - Clone Manager - Started cloned bot @AXIIVBOT
[16-Apr-25 17:44:37 - INFO] - Clone Manager - Started cloned bot @Elsarobot
[16-Apr-25 17:44:38 - INFO] - Clone Manager - Started cloned bot @QuizPlayBot
[16-Apr-25 17:44:39 - INFO] - Clone Manager - Started cloned bot @Savealbot
[16-Apr-25 17:52:01 - INFO] - root - Stop signal received (SIGINT). Exiting...
[16-Apr-25 17:52:02 - INFO] - root - Stop signal received (SIGINT). Exiting...
[16-Apr-25 17:52:10 - INFO] - lgram.core - Starting Bot...
[16-Apr-25 17:52:10 - INFO] - lgram - Main bot and clone bot management initialized.
[16-Apr-25 17:52:18 - INFO] - lgram.core - Running Deletor 
[16-Apr-25 17:52:19 - INFO] - lgram modules - Successfully imported all modules.
[16-Apr-25 17:52:19 - INFO] - Clone Manager - Restarting all cloned bots...
[16-Apr-25 17:52:20 - INFO] - Clone Manager - Started cloned bot @ImageGeneratorRoBot
[16-Apr-25 17:52:21 - INFO] - Clone Manager - Started cloned bot @Andipari364bot
[16-Apr-25 17:52:23 - INFO] - Clone Manager - Started cloned bot @AndreaPlaybot
[16-Apr-25 17:52:24 - INFO] - Clone Manager - Started cloned bot @AntispamfedBot
[16-Apr-25 17:52:25 - INFO] - Clone Manager - Started cloned bot @AXIIVBOT
[16-Apr-25 17:52:26 - INFO] - Clone Manager - Started cloned bot @Elsarobot
[16-Apr-25 17:52:27 - INFO] - Clone Manager - Started cloned bot @QuizPlayBot
[16-Apr-25 17:52:27 - INFO] - Clone Manager - Started cloned bot @Savealbot
[16-Apr-25 17:54:37 - INFO] - root - Stop signal received (SIGINT). Exiting...
[16-Apr-25 17:54:37 - INFO] - root - Stop signal received (SIGINT). Exiting...
[16-Apr-25 17:54:45 - INFO] - lgram.core - Starting Bot...
[16-Apr-25 17:54:45 - INFO] - lgram - Main bot and clone bot management initialized.
[16-Apr-25 17:54:54 - INFO] - lgram.core - Running Deletor 
[16-Apr-25 17:54:54 - INFO] - lgram modules - Successfully imported all modules.
[16-Apr-25 17:54:54 - INFO] - Clone Manager - Restarting all cloned bots...
[16-Apr-25 17:54:56 - INFO] - Clone Manager - Started cloned bot @ImageGeneratorRoBot
[16-Apr-25 17:54:57 - INFO] - Clone Manager - Started cloned bot @Andipari364bot
[16-Apr-25 17:54:58 - INFO] - Clone Manager - Started cloned bot @AndreaPlaybot
[16-Apr-25 17:54:59 - INFO] - Clone Manager - Started cloned bot @AntispamfedBot
[16-Apr-25 17:55:00 - INFO] - Clone Manager - Started cloned bot @AXIIVBOT
[16-Apr-25 17:55:01 - INFO] - Clone Manager - Started cloned bot @Elsarobot
[16-Apr-25 17:55:02 - INFO] - Clone Manager - Started cloned bot @QuizPlayBot
[16-Apr-25 17:55:03 - INFO] - Clone Manager - Started cloned bot @Savealbot
[16-Apr-25 17:55:57 - ERROR] - pyrogram.dispatcher - 'list' object is not callable
Traceback (most recent call last):
  File "C:\Users\psasw\AppData\Local\Packages\PythonSoftwareFoundation.Python.3.12_qbz5n2kfra8p0\LocalCache\local-packages\Python312\site-packages\pyrogram\dispatcher.py", line 240, in handler_worker
    await handler.callback(self.client, *args)
  File "C:\Users\psasw\OneDrive\Desktop\livegram\lgram\functions\wetdreams.py", line 162, in mybots
    bots = await list(mongo_db.bots.find())(user_id)
                 ^^^^^^^^^^^^^^^^^^^^^^^^^^^^^^^^^^^
TypeError: 'list' object is not callable
[16-Apr-25 17:55:59 - ERROR] - pyrogram.dispatcher - 'list' object is not callable
Traceback (most recent call last):
  File "C:\Users\psasw\AppData\Local\Packages\PythonSoftwareFoundation.Python.3.12_qbz5n2kfra8p0\LocalCache\local-packages\Python312\site-packages\pyrogram\dispatcher.py", line 240, in handler_worker
    await handler.callback(self.client, *args)
  File "C:\Users\psasw\OneDrive\Desktop\livegram\lgram\functions\wetdreams.py", line 162, in mybots
    bots = await list(mongo_db.bots.find())(user_id)
                 ^^^^^^^^^^^^^^^^^^^^^^^^^^^^^^^^^^^
TypeError: 'list' object is not callable
[16-Apr-25 17:56:19 - INFO] - root - Stop signal received (SIGINT). Exiting...
[16-Apr-25 17:56:19 - INFO] - root - Stop signal received (SIGINT). Exiting...
[16-Apr-25 17:56:32 - INFO] - lgram.core - Starting Bot...
[16-Apr-25 17:56:32 - INFO] - lgram - Main bot and clone bot management initialized.
[16-Apr-25 17:56:40 - INFO] - lgram.core - Running Deletor 
[16-Apr-25 17:56:40 - INFO] - lgram modules - Successfully imported all modules.
[16-Apr-25 17:56:40 - INFO] - Clone Manager - Restarting all cloned bots...
[16-Apr-25 17:56:42 - INFO] - Clone Manager - Started cloned bot @ImageGeneratorRoBot
[16-Apr-25 17:56:42 - INFO] - Clone Manager - Started cloned bot @Andipari364bot
[16-Apr-25 17:56:43 - INFO] - Clone Manager - Started cloned bot @AndreaPlaybot
[16-Apr-25 17:56:44 - INFO] - Clone Manager - Started cloned bot @AntispamfedBot
[16-Apr-25 17:56:45 - INFO] - Clone Manager - Started cloned bot @AXIIVBOT
[16-Apr-25 17:56:46 - INFO] - Clone Manager - Started cloned bot @Elsarobot
[16-Apr-25 17:56:47 - INFO] - Clone Manager - Started cloned bot @QuizPlayBot
[16-Apr-25 17:56:48 - INFO] - Clone Manager - Started cloned bot @Savealbot
[16-Apr-25 17:58:40 - INFO] - root - Stop signal received (SIGINT). Exiting...
[16-Apr-25 17:58:40 - INFO] - root - Stop signal received (SIGINT). Exiting...
[16-Apr-25 17:58:48 - INFO] - lgram.core - Starting Bot...
[16-Apr-25 17:58:48 - INFO] - lgram - Main bot and clone bot management initialized.
[16-Apr-25 17:58:57 - INFO] - lgram.core - Running Deletor 
[16-Apr-25 17:58:57 - INFO] - lgram modules - Successfully imported all modules.
[16-Apr-25 17:58:57 - INFO] - Clone Manager - Restarting all cloned bots...
[16-Apr-25 17:58:59 - INFO] - Clone Manager - Started cloned bot @ImageGeneratorRoBot
[16-Apr-25 17:59:00 - INFO] - Clone Manager - Started cloned bot @Andipari364bot
[16-Apr-25 17:59:01 - INFO] - Clone Manager - Started cloned bot @AndreaPlaybot
[16-Apr-25 17:59:02 - INFO] - Clone Manager - Started cloned bot @AntispamfedBot
[16-Apr-25 17:59:02 - INFO] - Clone Manager - Started cloned bot @AXIIVBOT
[16-Apr-25 17:59:03 - INFO] - Clone Manager - Started cloned bot @Elsarobot
[16-Apr-25 17:59:04 - INFO] - Clone Manager - Started cloned bot @QuizPlayBot
[16-Apr-25 17:59:05 - INFO] - Clone Manager - Started cloned bot @Savealbot
[16-Apr-25 18:02:41 - INFO] - root - Stop signal received (SIGINT). Exiting...
[16-Apr-25 18:02:41 - INFO] - root - Stop signal received (SIGINT). Exiting...
[16-Apr-25 18:02:49 - INFO] - lgram.core - Starting Bot...
[16-Apr-25 18:02:49 - INFO] - lgram - Main bot and clone bot management initialized.
[16-Apr-25 18:02:57 - INFO] - lgram.core - Running Deletor 
[16-Apr-25 18:02:57 - INFO] - lgram modules - Successfully imported all modules.
[16-Apr-25 18:02:57 - INFO] - Clone Manager - Restarting all cloned bots...
[16-Apr-25 18:02:59 - INFO] - Clone Manager - Started cloned bot @ImageGeneratorRoBot
[16-Apr-25 18:03:00 - INFO] - Clone Manager - Started cloned bot @Andipari364bot
[16-Apr-25 18:03:01 - INFO] - Clone Manager - Started cloned bot @AndreaPlaybot
[16-Apr-25 18:03:02 - INFO] - Clone Manager - Started cloned bot @AntispamfedBot
[16-Apr-25 18:03:03 - INFO] - Clone Manager - Started cloned bot @AXIIVBOT
[16-Apr-25 18:03:04 - INFO] - Clone Manager - Started cloned bot @Elsarobot
[16-Apr-25 18:03:05 - INFO] - Clone Manager - Started cloned bot @QuizPlayBot
[16-Apr-25 18:03:06 - INFO] - Clone Manager - Started cloned bot @Savealbot
[16-Apr-25 18:04:09 - INFO] - root - Stop signal received (SIGINT). Exiting...
[16-Apr-25 18:04:09 - INFO] - root - Stop signal received (SIGINT). Exiting...
[16-Apr-25 18:04:18 - INFO] - lgram.core - Starting Bot...
[16-Apr-25 18:04:18 - INFO] - lgram - Main bot and clone bot management initialized.
[16-Apr-25 18:04:28 - INFO] - lgram.core - Running Deletor 
[16-Apr-25 18:04:28 - INFO] - lgram modules - Successfully imported all modules.
[16-Apr-25 18:04:28 - INFO] - Clone Manager - Restarting all cloned bots...
[16-Apr-25 18:04:30 - INFO] - Clone Manager - Started cloned bot @ImageGeneratorRoBot
[16-Apr-25 18:04:31 - INFO] - Clone Manager - Started cloned bot @Andipari364bot
[16-Apr-25 18:04:32 - INFO] - Clone Manager - Started cloned bot @AndreaPlaybot
[16-Apr-25 18:04:33 - INFO] - Clone Manager - Started cloned bot @AntispamfedBot
[16-Apr-25 18:04:34 - INFO] - Clone Manager - Started cloned bot @AXIIVBOT
[16-Apr-25 18:04:35 - INFO] - Clone Manager - Started cloned bot @Elsarobot
[16-Apr-25 18:04:36 - INFO] - Clone Manager - Started cloned bot @QuizPlayBot
[16-Apr-25 18:04:37 - INFO] - Clone Manager - Started cloned bot @Savealbot
[16-Apr-25 18:06:11 - INFO] - root - Stop signal received (SIGINT). Exiting...
[16-Apr-25 18:06:11 - INFO] - root - Stop signal received (SIGINT). Exiting...
[16-Apr-25 18:06:28 - INFO] - lgram.core - Starting Bot...
[16-Apr-25 18:06:28 - INFO] - lgram - Main bot and clone bot management initialized.
[16-Apr-25 18:06:38 - INFO] - lgram.core - Running LgramBot 
[16-Apr-25 18:06:38 - INFO] - lgram modules - Successfully imported all modules.
[16-Apr-25 18:06:38 - INFO] - Clone Manager - Restarting all cloned bots...
[16-Apr-25 18:06:39 - INFO] - Clone Manager - Started cloned bot @ImageGeneratorRoBot
[16-Apr-25 18:06:40 - INFO] - Clone Manager - Started cloned bot @Andipari364bot
[16-Apr-25 18:06:41 - INFO] - Clone Manager - Started cloned bot @AndreaPlaybot
[16-Apr-25 18:06:42 - INFO] - Clone Manager - Started cloned bot @AntispamfedBot
[16-Apr-25 18:06:43 - INFO] - Clone Manager - Started cloned bot @AXIIVBOT
[16-Apr-25 18:06:44 - INFO] - Clone Manager - Started cloned bot @Elsarobot
[16-Apr-25 18:06:45 - INFO] - Clone Manager - Started cloned bot @QuizPlayBot
[16-Apr-25 18:06:46 - INFO] - Clone Manager - Started cloned bot @Savealbot
[16-Apr-25 18:13:59 - INFO] - root - Stop signal received (SIGINT). Exiting...
[16-Apr-25 18:14:00 - INFO] - root - Stop signal received (SIGINT). Exiting...
[16-Apr-25 18:14:08 - INFO] - lgram.core - Starting Bot...
[16-Apr-25 18:14:08 - INFO] - lgram - Main bot and clone bot management initialized.
[16-Apr-25 18:14:15 - INFO] - lgram.core - Running LgramBot 
[16-Apr-25 18:14:16 - INFO] - lgram modules - Successfully imported all modules.
[16-Apr-25 18:14:16 - INFO] - Clone Manager - Restarting all cloned bots...
[16-Apr-25 18:14:17 - INFO] - Clone Manager - Started cloned bot @ImageGeneratorRoBot
[16-Apr-25 18:14:18 - INFO] - Clone Manager - Started cloned bot @Andipari364bot
[16-Apr-25 18:14:19 - INFO] - Clone Manager - Started cloned bot @AndreaPlaybot
[16-Apr-25 18:14:20 - INFO] - Clone Manager - Started cloned bot @AntispamfedBot
[16-Apr-25 18:14:20 - INFO] - Clone Manager - Started cloned bot @AXIIVBOT
[16-Apr-25 18:14:21 - INFO] - Clone Manager - Started cloned bot @Elsarobot
[16-Apr-25 18:14:22 - INFO] - Clone Manager - Started cloned bot @QuizPlayBot
[16-Apr-25 18:14:23 - ERROR] - Clone Manager - Error @Savealbot :Telegram says: [401 SESSION_REVOKED] - The authorization has been invalidated, because of the user terminating all sessions (caused by "updates.GetState")
Traceback (most recent call last):
  File "C:\Users\psasw\OneDrive\Desktop\livegram\lgram\__main__.py", line 42, in restart_clones
    await ai.start()
  File "C:\Users\psasw\AppData\Local\Packages\PythonSoftwareFoundation.Python.3.12_qbz5n2kfra8p0\LocalCache\local-packages\Python312\site-packages\pyrogram\methods\utilities\start.py", line 68, in start
    await self.invoke(raw.functions.updates.GetState())
  File "C:\Users\psasw\AppData\Local\Packages\PythonSoftwareFoundation.Python.3.12_qbz5n2kfra8p0\LocalCache\local-packages\Python312\site-packages\pyrogram\methods\advanced\invoke.py", line 79, in invoke
    r = await self.session.invoke(
        ^^^^^^^^^^^^^^^^^^^^^^^^^^
  File "C:\Users\psasw\AppData\Local\Packages\PythonSoftwareFoundation.Python.3.12_qbz5n2kfra8p0\LocalCache\local-packages\Python312\site-packages\pyrogram\session\session.py", line 389, in invoke
    return await self.send(query, timeout=timeout)
           ^^^^^^^^^^^^^^^^^^^^^^^^^^^^^^^^^^^^^^^
  File "C:\Users\psasw\AppData\Local\Packages\PythonSoftwareFoundation.Python.3.12_qbz5n2kfra8p0\LocalCache\local-packages\Python312\site-packages\pyrogram\session\session.py", line 357, in send
    RPCError.raise_it(result, type(data))
  File "C:\Users\psasw\AppData\Local\Packages\PythonSoftwareFoundation.Python.3.12_qbz5n2kfra8p0\LocalCache\local-packages\Python312\site-packages\pyrogram\errors\rpc_error.py", line 91, in raise_it
    raise getattr(
pyrogram.errors.exceptions.unauthorized_401.SessionRevoked: Telegram says: [401 SESSION_REVOKED] - The authorization has been invalidated, because of the user terminating all sessions (caused by "updates.GetState")
[16-Apr-25 18:14:24 - ERROR] - Clone Manager - Error @MissIvoryBot :Telegram says: [401 SESSION_REVOKED] - The authorization has been invalidated, because of the user terminating all sessions (caused by "updates.GetState")
Traceback (most recent call last):
  File "C:\Users\psasw\OneDrive\Desktop\livegram\lgram\__main__.py", line 42, in restart_clones
    await ai.start()
  File "C:\Users\psasw\AppData\Local\Packages\PythonSoftwareFoundation.Python.3.12_qbz5n2kfra8p0\LocalCache\local-packages\Python312\site-packages\pyrogram\methods\utilities\start.py", line 68, in start
    await self.invoke(raw.functions.updates.GetState())
  File "C:\Users\psasw\AppData\Local\Packages\PythonSoftwareFoundation.Python.3.12_qbz5n2kfra8p0\LocalCache\local-packages\Python312\site-packages\pyrogram\methods\advanced\invoke.py", line 79, in invoke
    r = await self.session.invoke(
        ^^^^^^^^^^^^^^^^^^^^^^^^^^
  File "C:\Users\psasw\AppData\Local\Packages\PythonSoftwareFoundation.Python.3.12_qbz5n2kfra8p0\LocalCache\local-packages\Python312\site-packages\pyrogram\session\session.py", line 389, in invoke
    return await self.send(query, timeout=timeout)
           ^^^^^^^^^^^^^^^^^^^^^^^^^^^^^^^^^^^^^^^
  File "C:\Users\psasw\AppData\Local\Packages\PythonSoftwareFoundation.Python.3.12_qbz5n2kfra8p0\LocalCache\local-packages\Python312\site-packages\pyrogram\session\session.py", line 357, in send
    RPCError.raise_it(result, type(data))
  File "C:\Users\psasw\AppData\Local\Packages\PythonSoftwareFoundation.Python.3.12_qbz5n2kfra8p0\LocalCache\local-packages\Python312\site-packages\pyrogram\errors\rpc_error.py", line 91, in raise_it
    raise getattr(
pyrogram.errors.exceptions.unauthorized_401.SessionRevoked: Telegram says: [401 SESSION_REVOKED] - The authorization has been invalidated, because of the user terminating all sessions (caused by "updates.GetState")
[16-Apr-25 18:20:33 - INFO] - root - Stop signal received (SIGINT). Exiting...
[16-Apr-25 18:20:34 - INFO] - root - Stop signal received (SIGINT). Exiting...
[16-Apr-25 18:21:34 - INFO] - lgram.core - Starting Bot...
[16-Apr-25 18:21:34 - INFO] - lgram - Main bot and clone bot management initialized.
[16-Apr-25 18:21:46 - INFO] - lgram.core - Running LgramBot 
[16-Apr-25 18:21:46 - INFO] - lgram modules - Successfully imported all modules.
[16-Apr-25 18:21:46 - INFO] - Clone Manager - Restarting all cloned bots...
[16-Apr-25 18:21:48 - INFO] - Clone Manager - Started cloned bot @ImageGeneratorRoBot
[16-Apr-25 18:21:49 - INFO] - Clone Manager - Started cloned bot @Andipari364bot
[16-Apr-25 18:21:50 - INFO] - Clone Manager - Started cloned bot @AndreaPlaybot
[16-Apr-25 18:21:51 - INFO] - Clone Manager - Started cloned bot @AntispamfedBot
[16-Apr-25 18:21:52 - INFO] - Clone Manager - Started cloned bot @AXIIVBOT
[16-Apr-25 18:21:53 - INFO] - Clone Manager - Started cloned bot @Elsarobot
[16-Apr-25 18:21:54 - INFO] - Clone Manager - Started cloned bot @QuizPlayBot
[16-Apr-25 18:21:54 - ERROR] - Clone Manager - Error @Savealbot :Telegram says: [401 SESSION_REVOKED] - The authorization has been invalidated, because of the user terminating all sessions (caused by "updates.GetState")
Traceback (most recent call last):
  File "C:\Users\psasw\OneDrive\Desktop\livegram\lgram\__main__.py", line 42, in restart_clones
    await ai.start()
  File "C:\Users\psasw\AppData\Local\Packages\PythonSoftwareFoundation.Python.3.12_qbz5n2kfra8p0\LocalCache\local-packages\Python312\site-packages\pyrogram\methods\utilities\start.py", line 68, in start
    await self.invoke(raw.functions.updates.GetState())
  File "C:\Users\psasw\AppData\Local\Packages\PythonSoftwareFoundation.Python.3.12_qbz5n2kfra8p0\LocalCache\local-packages\Python312\site-packages\pyrogram\methods\advanced\invoke.py", line 79, in invoke
    r = await self.session.invoke(
        ^^^^^^^^^^^^^^^^^^^^^^^^^^
  File "C:\Users\psasw\AppData\Local\Packages\PythonSoftwareFoundation.Python.3.12_qbz5n2kfra8p0\LocalCache\local-packages\Python312\site-packages\pyrogram\session\session.py", line 389, in invoke
    return await self.send(query, timeout=timeout)
           ^^^^^^^^^^^^^^^^^^^^^^^^^^^^^^^^^^^^^^^
  File "C:\Users\psasw\AppData\Local\Packages\PythonSoftwareFoundation.Python.3.12_qbz5n2kfra8p0\LocalCache\local-packages\Python312\site-packages\pyrogram\session\session.py", line 357, in send
    RPCError.raise_it(result, type(data))
  File "C:\Users\psasw\AppData\Local\Packages\PythonSoftwareFoundation.Python.3.12_qbz5n2kfra8p0\LocalCache\local-packages\Python312\site-packages\pyrogram\errors\rpc_error.py", line 91, in raise_it
    raise getattr(
pyrogram.errors.exceptions.unauthorized_401.SessionRevoked: Telegram says: [401 SESSION_REVOKED] - The authorization has been invalidated, because of the user terminating all sessions (caused by "updates.GetState")
[16-Apr-25 18:21:55 - ERROR] - Clone Manager - Error @MissIvoryBot :Telegram says: [401 SESSION_REVOKED] - The authorization has been invalidated, because of the user terminating all sessions (caused by "updates.GetState")
Traceback (most recent call last):
  File "C:\Users\psasw\OneDrive\Desktop\livegram\lgram\__main__.py", line 42, in restart_clones
    await ai.start()
  File "C:\Users\psasw\AppData\Local\Packages\PythonSoftwareFoundation.Python.3.12_qbz5n2kfra8p0\LocalCache\local-packages\Python312\site-packages\pyrogram\methods\utilities\start.py", line 68, in start
    await self.invoke(raw.functions.updates.GetState())
  File "C:\Users\psasw\AppData\Local\Packages\PythonSoftwareFoundation.Python.3.12_qbz5n2kfra8p0\LocalCache\local-packages\Python312\site-packages\pyrogram\methods\advanced\invoke.py", line 79, in invoke
    r = await self.session.invoke(
        ^^^^^^^^^^^^^^^^^^^^^^^^^^
  File "C:\Users\psasw\AppData\Local\Packages\PythonSoftwareFoundation.Python.3.12_qbz5n2kfra8p0\LocalCache\local-packages\Python312\site-packages\pyrogram\session\session.py", line 389, in invoke
    return await self.send(query, timeout=timeout)
           ^^^^^^^^^^^^^^^^^^^^^^^^^^^^^^^^^^^^^^^
  File "C:\Users\psasw\AppData\Local\Packages\PythonSoftwareFoundation.Python.3.12_qbz5n2kfra8p0\LocalCache\local-packages\Python312\site-packages\pyrogram\session\session.py", line 357, in send
    RPCError.raise_it(result, type(data))
  File "C:\Users\psasw\AppData\Local\Packages\PythonSoftwareFoundation.Python.3.12_qbz5n2kfra8p0\LocalCache\local-packages\Python312\site-packages\pyrogram\errors\rpc_error.py", line 91, in raise_it
    raise getattr(
pyrogram.errors.exceptions.unauthorized_401.SessionRevoked: Telegram says: [401 SESSION_REVOKED] - The authorization has been invalidated, because of the user terminating all sessions (caused by "updates.GetState")
[16-Apr-25 18:22:03 - INFO] - Clone Manager - Started cloned bot @IsebellaBot
[16-Apr-25 18:22:08 - INFO] - Clone Manager - Started cloned bot @BESTMEDIA000BOT
[16-Apr-25 18:23:02 - INFO] - root - Stop signal received (SIGINT). Exiting...
[16-Apr-25 18:23:10 - INFO] - lgram.core - Starting Bot...
[16-Apr-25 18:23:10 - INFO] - lgram - Main bot and clone bot management initialized.
[16-Apr-25 18:23:17 - INFO] - lgram.core - Running LgramBot 
[16-Apr-25 18:23:18 - INFO] - lgram modules - Successfully imported all modules.
[16-Apr-25 18:23:18 - INFO] - Clone Manager - Restarting all cloned bots...
[16-Apr-25 18:23:19 - INFO] - Clone Manager - Started cloned bot @ImageGeneratorRoBot
[16-Apr-25 18:23:20 - INFO] - Clone Manager - Started cloned bot @Andipari364bot
[16-Apr-25 18:23:21 - INFO] - Clone Manager - Started cloned bot @AndreaPlaybot
[16-Apr-25 18:23:22 - INFO] - Clone Manager - Started cloned bot @AntispamfedBot
[16-Apr-25 18:23:23 - INFO] - Clone Manager - Started cloned bot @AXIIVBOT
[16-Apr-25 18:23:24 - INFO] - Clone Manager - Started cloned bot @Elsarobot
[16-Apr-25 18:23:25 - INFO] - Clone Manager - Started cloned bot @QuizPlayBot
[16-Apr-25 18:23:26 - ERROR] - Clone Manager - Error @Savealbot :Telegram says: [401 SESSION_REVOKED] - The authorization has been invalidated, because of the user terminating all sessions (caused by "updates.GetState")
Traceback (most recent call last):
  File "C:\Users\psasw\OneDrive\Desktop\livegram\lgram\__main__.py", line 42, in restart_clones
    await ai.start()
  File "C:\Users\psasw\AppData\Local\Packages\PythonSoftwareFoundation.Python.3.12_qbz5n2kfra8p0\LocalCache\local-packages\Python312\site-packages\pyrogram\methods\utilities\start.py", line 68, in start
    await self.invoke(raw.functions.updates.GetState())
  File "C:\Users\psasw\AppData\Local\Packages\PythonSoftwareFoundation.Python.3.12_qbz5n2kfra8p0\LocalCache\local-packages\Python312\site-packages\pyrogram\methods\advanced\invoke.py", line 79, in invoke
    r = await self.session.invoke(
        ^^^^^^^^^^^^^^^^^^^^^^^^^^
  File "C:\Users\psasw\AppData\Local\Packages\PythonSoftwareFoundation.Python.3.12_qbz5n2kfra8p0\LocalCache\local-packages\Python312\site-packages\pyrogram\session\session.py", line 389, in invoke
    return await self.send(query, timeout=timeout)
           ^^^^^^^^^^^^^^^^^^^^^^^^^^^^^^^^^^^^^^^
  File "C:\Users\psasw\AppData\Local\Packages\PythonSoftwareFoundation.Python.3.12_qbz5n2kfra8p0\LocalCache\local-packages\Python312\site-packages\pyrogram\session\session.py", line 357, in send
    RPCError.raise_it(result, type(data))
  File "C:\Users\psasw\AppData\Local\Packages\PythonSoftwareFoundation.Python.3.12_qbz5n2kfra8p0\LocalCache\local-packages\Python312\site-packages\pyrogram\errors\rpc_error.py", line 91, in raise_it
    raise getattr(
pyrogram.errors.exceptions.unauthorized_401.SessionRevoked: Telegram says: [401 SESSION_REVOKED] - The authorization has been invalidated, because of the user terminating all sessions (caused by "updates.GetState")
[16-Apr-25 18:23:27 - ERROR] - Clone Manager - Error @MissIvoryBot :Telegram says: [401 SESSION_REVOKED] - The authorization has been invalidated, because of the user terminating all sessions (caused by "updates.GetState")
Traceback (most recent call last):
  File "C:\Users\psasw\OneDrive\Desktop\livegram\lgram\__main__.py", line 42, in restart_clones
    await ai.start()
  File "C:\Users\psasw\AppData\Local\Packages\PythonSoftwareFoundation.Python.3.12_qbz5n2kfra8p0\LocalCache\local-packages\Python312\site-packages\pyrogram\methods\utilities\start.py", line 68, in start
    await self.invoke(raw.functions.updates.GetState())
  File "C:\Users\psasw\AppData\Local\Packages\PythonSoftwareFoundation.Python.3.12_qbz5n2kfra8p0\LocalCache\local-packages\Python312\site-packages\pyrogram\methods\advanced\invoke.py", line 79, in invoke
    r = await self.session.invoke(
        ^^^^^^^^^^^^^^^^^^^^^^^^^^
  File "C:\Users\psasw\AppData\Local\Packages\PythonSoftwareFoundation.Python.3.12_qbz5n2kfra8p0\LocalCache\local-packages\Python312\site-packages\pyrogram\session\session.py", line 389, in invoke
    return await self.send(query, timeout=timeout)
           ^^^^^^^^^^^^^^^^^^^^^^^^^^^^^^^^^^^^^^^
  File "C:\Users\psasw\AppData\Local\Packages\PythonSoftwareFoundation.Python.3.12_qbz5n2kfra8p0\LocalCache\local-packages\Python312\site-packages\pyrogram\session\session.py", line 357, in send
    RPCError.raise_it(result, type(data))
  File "C:\Users\psasw\AppData\Local\Packages\PythonSoftwareFoundation.Python.3.12_qbz5n2kfra8p0\LocalCache\local-packages\Python312\site-packages\pyrogram\errors\rpc_error.py", line 91, in raise_it
    raise getattr(
pyrogram.errors.exceptions.unauthorized_401.SessionRevoked: Telegram says: [401 SESSION_REVOKED] - The authorization has been invalidated, because of the user terminating all sessions (caused by "updates.GetState")
[16-Apr-25 18:23:28 - INFO] - Clone Manager - Started cloned bot @IsebellaBot
[16-Apr-25 18:23:29 - INFO] - Clone Manager - Started cloned bot @BESTMEDIA000BOT
[16-Apr-25 18:33:17 - INFO] - root - Stop signal received (SIGINT). Exiting...
[16-Apr-25 18:54:22 - INFO] - lgram.core - Starting Bot...
[16-Apr-25 18:54:22 - INFO] - lgram - Main bot and clone bot management initialized.
[16-Apr-25 18:54:31 - INFO] - lgram.core - Running LgramBot 
[16-Apr-25 18:54:31 - INFO] - lgram modules - Successfully imported all modules.
[16-Apr-25 18:54:31 - INFO] - Clone Manager - Restarting all cloned bots...
[16-Apr-25 18:54:33 - INFO] - Clone Manager - Started cloned bot @ImageGeneratorRoBot
[16-Apr-25 18:54:34 - INFO] - Clone Manager - Started cloned bot @Andipari364bot
[16-Apr-25 18:54:35 - INFO] - Clone Manager - Started cloned bot @AndreaPlaybot
[16-Apr-25 18:54:36 - INFO] - Clone Manager - Started cloned bot @AntispamfedBot
[16-Apr-25 18:54:37 - INFO] - Clone Manager - Started cloned bot @AXIIVBOT
[16-Apr-25 18:54:37 - INFO] - Clone Manager - Started cloned bot @Elsarobot
[16-Apr-25 18:54:38 - INFO] - Clone Manager - Started cloned bot @QuizPlayBot
[16-Apr-25 18:54:39 - ERROR] - Clone Manager - Error @Savealbot :Telegram says: [401 SESSION_REVOKED] - The authorization has been invalidated, because of the user terminating all sessions (caused by "updates.GetState")
Traceback (most recent call last):
  File "C:\Users\psasw\OneDrive\Desktop\livegram\lgram\__main__.py", line 42, in restart_clones
    await ai.start()
  File "C:\Users\psasw\AppData\Local\Packages\PythonSoftwareFoundation.Python.3.12_qbz5n2kfra8p0\LocalCache\local-packages\Python312\site-packages\pyrogram\methods\utilities\start.py", line 68, in start
    await self.invoke(raw.functions.updates.GetState())
  File "C:\Users\psasw\AppData\Local\Packages\PythonSoftwareFoundation.Python.3.12_qbz5n2kfra8p0\LocalCache\local-packages\Python312\site-packages\pyrogram\methods\advanced\invoke.py", line 79, in invoke
    r = await self.session.invoke(
        ^^^^^^^^^^^^^^^^^^^^^^^^^^
  File "C:\Users\psasw\AppData\Local\Packages\PythonSoftwareFoundation.Python.3.12_qbz5n2kfra8p0\LocalCache\local-packages\Python312\site-packages\pyrogram\session\session.py", line 389, in invoke
    return await self.send(query, timeout=timeout)
           ^^^^^^^^^^^^^^^^^^^^^^^^^^^^^^^^^^^^^^^
  File "C:\Users\psasw\AppData\Local\Packages\PythonSoftwareFoundation.Python.3.12_qbz5n2kfra8p0\LocalCache\local-packages\Python312\site-packages\pyrogram\session\session.py", line 357, in send
    RPCError.raise_it(result, type(data))
  File "C:\Users\psasw\AppData\Local\Packages\PythonSoftwareFoundation.Python.3.12_qbz5n2kfra8p0\LocalCache\local-packages\Python312\site-packages\pyrogram\errors\rpc_error.py", line 91, in raise_it
    raise getattr(
pyrogram.errors.exceptions.unauthorized_401.SessionRevoked: Telegram says: [401 SESSION_REVOKED] - The authorization has been invalidated, because of the user terminating all sessions (caused by "updates.GetState")
[16-Apr-25 18:54:40 - ERROR] - Clone Manager - Error @MissIvoryBot :Telegram says: [401 SESSION_REVOKED] - The authorization has been invalidated, because of the user terminating all sessions (caused by "updates.GetState")
Traceback (most recent call last):
  File "C:\Users\psasw\OneDrive\Desktop\livegram\lgram\__main__.py", line 42, in restart_clones
    await ai.start()
  File "C:\Users\psasw\AppData\Local\Packages\PythonSoftwareFoundation.Python.3.12_qbz5n2kfra8p0\LocalCache\local-packages\Python312\site-packages\pyrogram\methods\utilities\start.py", line 68, in start
    await self.invoke(raw.functions.updates.GetState())
  File "C:\Users\psasw\AppData\Local\Packages\PythonSoftwareFoundation.Python.3.12_qbz5n2kfra8p0\LocalCache\local-packages\Python312\site-packages\pyrogram\methods\advanced\invoke.py", line 79, in invoke
    r = await self.session.invoke(
        ^^^^^^^^^^^^^^^^^^^^^^^^^^
  File "C:\Users\psasw\AppData\Local\Packages\PythonSoftwareFoundation.Python.3.12_qbz5n2kfra8p0\LocalCache\local-packages\Python312\site-packages\pyrogram\session\session.py", line 389, in invoke
    return await self.send(query, timeout=timeout)
           ^^^^^^^^^^^^^^^^^^^^^^^^^^^^^^^^^^^^^^^
  File "C:\Users\psasw\AppData\Local\Packages\PythonSoftwareFoundation.Python.3.12_qbz5n2kfra8p0\LocalCache\local-packages\Python312\site-packages\pyrogram\session\session.py", line 357, in send
    RPCError.raise_it(result, type(data))
  File "C:\Users\psasw\AppData\Local\Packages\PythonSoftwareFoundation.Python.3.12_qbz5n2kfra8p0\LocalCache\local-packages\Python312\site-packages\pyrogram\errors\rpc_error.py", line 91, in raise_it
    raise getattr(
pyrogram.errors.exceptions.unauthorized_401.SessionRevoked: Telegram says: [401 SESSION_REVOKED] - The authorization has been invalidated, because of the user terminating all sessions (caused by "updates.GetState")
[16-Apr-25 18:54:41 - INFO] - Clone Manager - Started cloned bot @IsebellaBot
[16-Apr-25 18:54:42 - INFO] - Clone Manager - Started cloned bot @BESTMEDIA000BOT
[16-Apr-25 18:58:08 - INFO] - root - Stop signal received (SIGINT). Exiting...
[16-Apr-25 18:58:08 - INFO] - root - Stop signal received (SIGINT). Exiting...
[16-Apr-25 18:58:08 - INFO] - root - Stop signal received (SIGINT). Exiting...
[16-Apr-25 18:58:29 - INFO] - lgram.core - Starting Bot...
[16-Apr-25 18:58:29 - INFO] - lgram - Main bot and clone bot management initialized.
[16-Apr-25 18:58:36 - INFO] - lgram.core - Running LgramBot 
[16-Apr-25 18:58:36 - INFO] - lgram modules - Successfully imported all modules.
[16-Apr-25 18:58:36 - INFO] - Clone Manager - Restarting all cloned bots...
[16-Apr-25 18:58:38 - INFO] - Clone Manager - Started cloned bot @ImageGeneratorRoBot
[16-Apr-25 18:58:39 - INFO] - Clone Manager - Started cloned bot @Andipari364bot
[16-Apr-25 18:58:40 - INFO] - Clone Manager - Started cloned bot @AndreaPlaybot
[16-Apr-25 18:58:41 - INFO] - Clone Manager - Started cloned bot @AntispamfedBot
[16-Apr-25 18:58:42 - INFO] - Clone Manager - Started cloned bot @AXIIVBOT
[16-Apr-25 18:58:43 - INFO] - Clone Manager - Started cloned bot @Elsarobot
[16-Apr-25 18:58:44 - INFO] - Clone Manager - Started cloned bot @QuizPlayBot
[16-Apr-25 18:58:45 - ERROR] - Clone Manager - Error @Savealbot :Telegram says: [401 SESSION_REVOKED] - The authorization has been invalidated, because of the user terminating all sessions (caused by "updates.GetState")
Traceback (most recent call last):
  File "C:\Users\psasw\OneDrive\Desktop\livegram\lgram\__main__.py", line 42, in restart_clones
    await ai.start()
  File "C:\Users\psasw\AppData\Local\Packages\PythonSoftwareFoundation.Python.3.12_qbz5n2kfra8p0\LocalCache\local-packages\Python312\site-packages\pyrogram\methods\utilities\start.py", line 68, in start
    await self.invoke(raw.functions.updates.GetState())
  File "C:\Users\psasw\AppData\Local\Packages\PythonSoftwareFoundation.Python.3.12_qbz5n2kfra8p0\LocalCache\local-packages\Python312\site-packages\pyrogram\methods\advanced\invoke.py", line 79, in invoke
    r = await self.session.invoke(
        ^^^^^^^^^^^^^^^^^^^^^^^^^^
  File "C:\Users\psasw\AppData\Local\Packages\PythonSoftwareFoundation.Python.3.12_qbz5n2kfra8p0\LocalCache\local-packages\Python312\site-packages\pyrogram\session\session.py", line 389, in invoke
    return await self.send(query, timeout=timeout)
           ^^^^^^^^^^^^^^^^^^^^^^^^^^^^^^^^^^^^^^^
  File "C:\Users\psasw\AppData\Local\Packages\PythonSoftwareFoundation.Python.3.12_qbz5n2kfra8p0\LocalCache\local-packages\Python312\site-packages\pyrogram\session\session.py", line 357, in send
    RPCError.raise_it(result, type(data))
  File "C:\Users\psasw\AppData\Local\Packages\PythonSoftwareFoundation.Python.3.12_qbz5n2kfra8p0\LocalCache\local-packages\Python312\site-packages\pyrogram\errors\rpc_error.py", line 91, in raise_it
    raise getattr(
pyrogram.errors.exceptions.unauthorized_401.SessionRevoked: Telegram says: [401 SESSION_REVOKED] - The authorization has been invalidated, because of the user terminating all sessions (caused by "updates.GetState")
[16-Apr-25 18:58:46 - ERROR] - Clone Manager - Error @MissIvoryBot :Telegram says: [401 SESSION_REVOKED] - The authorization has been invalidated, because of the user terminating all sessions (caused by "updates.GetState")
Traceback (most recent call last):
  File "C:\Users\psasw\OneDrive\Desktop\livegram\lgram\__main__.py", line 42, in restart_clones
    await ai.start()
  File "C:\Users\psasw\AppData\Local\Packages\PythonSoftwareFoundation.Python.3.12_qbz5n2kfra8p0\LocalCache\local-packages\Python312\site-packages\pyrogram\methods\utilities\start.py", line 68, in start
    await self.invoke(raw.functions.updates.GetState())
  File "C:\Users\psasw\AppData\Local\Packages\PythonSoftwareFoundation.Python.3.12_qbz5n2kfra8p0\LocalCache\local-packages\Python312\site-packages\pyrogram\methods\advanced\invoke.py", line 79, in invoke
    r = await self.session.invoke(
        ^^^^^^^^^^^^^^^^^^^^^^^^^^
  File "C:\Users\psasw\AppData\Local\Packages\PythonSoftwareFoundation.Python.3.12_qbz5n2kfra8p0\LocalCache\local-packages\Python312\site-packages\pyrogram\session\session.py", line 389, in invoke
    return await self.send(query, timeout=timeout)
           ^^^^^^^^^^^^^^^^^^^^^^^^^^^^^^^^^^^^^^^
  File "C:\Users\psasw\AppData\Local\Packages\PythonSoftwareFoundation.Python.3.12_qbz5n2kfra8p0\LocalCache\local-packages\Python312\site-packages\pyrogram\session\session.py", line 357, in send
    RPCError.raise_it(result, type(data))
  File "C:\Users\psasw\AppData\Local\Packages\PythonSoftwareFoundation.Python.3.12_qbz5n2kfra8p0\LocalCache\local-packages\Python312\site-packages\pyrogram\errors\rpc_error.py", line 91, in raise_it
    raise getattr(
pyrogram.errors.exceptions.unauthorized_401.SessionRevoked: Telegram says: [401 SESSION_REVOKED] - The authorization has been invalidated, because of the user terminating all sessions (caused by "updates.GetState")
[16-Apr-25 18:58:46 - INFO] - Clone Manager - Started cloned bot @IsebellaBot
[16-Apr-25 18:58:47 - INFO] - Clone Manager - Started cloned bot @BESTMEDIA000BOT
[16-Apr-25 19:01:42 - INFO] - root - Stop signal received (SIGINT). Exiting...
[16-Apr-25 19:01:42 - INFO] - root - Stop signal received (SIGINT). Exiting...
[16-Apr-25 19:02:17 - INFO] - lgram.core - Starting Bot...
[16-Apr-25 19:02:17 - INFO] - lgram - Main bot and clone bot management initialized.
[16-Apr-25 19:02:25 - INFO] - lgram.core - Running LgramBot 
[16-Apr-25 19:02:25 - INFO] - lgram modules - Successfully imported all modules.
[16-Apr-25 19:02:25 - INFO] - Clone Manager - Restarting all cloned bots...
[16-Apr-25 19:02:27 - INFO] - Clone Manager - Started cloned bot @ImageGeneratorRoBot
[16-Apr-25 19:02:28 - INFO] - Clone Manager - Started cloned bot @Andipari364bot
[16-Apr-25 19:02:29 - INFO] - Clone Manager - Started cloned bot @AndreaPlaybot
[16-Apr-25 19:02:30 - INFO] - Clone Manager - Started cloned bot @AntispamfedBot
[16-Apr-25 19:02:31 - INFO] - Clone Manager - Started cloned bot @AXIIVBOT
[16-Apr-25 19:02:31 - INFO] - Clone Manager - Started cloned bot @Elsarobot
[16-Apr-25 19:02:32 - INFO] - Clone Manager - Started cloned bot @QuizPlayBot
[16-Apr-25 19:02:33 - ERROR] - Clone Manager - Error @Savealbot :Telegram says: [401 SESSION_REVOKED] - The authorization has been invalidated, because of the user terminating all sessions (caused by "updates.GetState")
Traceback (most recent call last):
  File "C:\Users\psasw\OneDrive\Desktop\livegram\lgram\__main__.py", line 42, in restart_clones
    await ai.start()
  File "C:\Users\psasw\AppData\Local\Packages\PythonSoftwareFoundation.Python.3.12_qbz5n2kfra8p0\LocalCache\local-packages\Python312\site-packages\pyrogram\methods\utilities\start.py", line 68, in start
    await self.invoke(raw.functions.updates.GetState())
  File "C:\Users\psasw\AppData\Local\Packages\PythonSoftwareFoundation.Python.3.12_qbz5n2kfra8p0\LocalCache\local-packages\Python312\site-packages\pyrogram\methods\advanced\invoke.py", line 79, in invoke
    r = await self.session.invoke(
        ^^^^^^^^^^^^^^^^^^^^^^^^^^
  File "C:\Users\psasw\AppData\Local\Packages\PythonSoftwareFoundation.Python.3.12_qbz5n2kfra8p0\LocalCache\local-packages\Python312\site-packages\pyrogram\session\session.py", line 389, in invoke
    return await self.send(query, timeout=timeout)
           ^^^^^^^^^^^^^^^^^^^^^^^^^^^^^^^^^^^^^^^
  File "C:\Users\psasw\AppData\Local\Packages\PythonSoftwareFoundation.Python.3.12_qbz5n2kfra8p0\LocalCache\local-packages\Python312\site-packages\pyrogram\session\session.py", line 357, in send
    RPCError.raise_it(result, type(data))
  File "C:\Users\psasw\AppData\Local\Packages\PythonSoftwareFoundation.Python.3.12_qbz5n2kfra8p0\LocalCache\local-packages\Python312\site-packages\pyrogram\errors\rpc_error.py", line 91, in raise_it
    raise getattr(
pyrogram.errors.exceptions.unauthorized_401.SessionRevoked: Telegram says: [401 SESSION_REVOKED] - The authorization has been invalidated, because of the user terminating all sessions (caused by "updates.GetState")
[16-Apr-25 19:02:34 - ERROR] - Clone Manager - Error @MissIvoryBot :Telegram says: [401 SESSION_REVOKED] - The authorization has been invalidated, because of the user terminating all sessions (caused by "updates.GetState")
Traceback (most recent call last):
  File "C:\Users\psasw\OneDrive\Desktop\livegram\lgram\__main__.py", line 42, in restart_clones
    await ai.start()
  File "C:\Users\psasw\AppData\Local\Packages\PythonSoftwareFoundation.Python.3.12_qbz5n2kfra8p0\LocalCache\local-packages\Python312\site-packages\pyrogram\methods\utilities\start.py", line 68, in start
    await self.invoke(raw.functions.updates.GetState())
  File "C:\Users\psasw\AppData\Local\Packages\PythonSoftwareFoundation.Python.3.12_qbz5n2kfra8p0\LocalCache\local-packages\Python312\site-packages\pyrogram\methods\advanced\invoke.py", line 79, in invoke
    r = await self.session.invoke(
        ^^^^^^^^^^^^^^^^^^^^^^^^^^
  File "C:\Users\psasw\AppData\Local\Packages\PythonSoftwareFoundation.Python.3.12_qbz5n2kfra8p0\LocalCache\local-packages\Python312\site-packages\pyrogram\session\session.py", line 389, in invoke
    return await self.send(query, timeout=timeout)
           ^^^^^^^^^^^^^^^^^^^^^^^^^^^^^^^^^^^^^^^
  File "C:\Users\psasw\AppData\Local\Packages\PythonSoftwareFoundation.Python.3.12_qbz5n2kfra8p0\LocalCache\local-packages\Python312\site-packages\pyrogram\session\session.py", line 357, in send
    RPCError.raise_it(result, type(data))
  File "C:\Users\psasw\AppData\Local\Packages\PythonSoftwareFoundation.Python.3.12_qbz5n2kfra8p0\LocalCache\local-packages\Python312\site-packages\pyrogram\errors\rpc_error.py", line 91, in raise_it
    raise getattr(
pyrogram.errors.exceptions.unauthorized_401.SessionRevoked: Telegram says: [401 SESSION_REVOKED] - The authorization has been invalidated, because of the user terminating all sessions (caused by "updates.GetState")
[16-Apr-25 19:02:35 - INFO] - Clone Manager - Started cloned bot @IsebellaBot
[16-Apr-25 19:02:36 - INFO] - Clone Manager - Started cloned bot @BESTMEDIA000BOT
[16-Apr-25 19:06:01 - INFO] - root - Stop signal received (SIGINT). Exiting...
[16-Apr-25 19:06:01 - INFO] - root - Stop signal received (SIGINT). Exiting...
[16-Apr-25 19:06:01 - INFO] - root - Stop signal received (SIGINT). Exiting...
[16-Apr-25 19:06:10 - INFO] - lgram.core - Starting Bot...
[16-Apr-25 19:06:10 - INFO] - lgram - Main bot and clone bot management initialized.
[16-Apr-25 19:06:18 - INFO] - lgram.core - Running LgramBot 
[16-Apr-25 19:06:19 - INFO] - lgram modules - Successfully imported all modules.
[16-Apr-25 19:06:19 - INFO] - Clone Manager - Restarting all cloned bots...
[16-Apr-25 19:06:20 - INFO] - Clone Manager - Started cloned bot @ImageGeneratorRoBot
[16-Apr-25 19:06:21 - INFO] - Clone Manager - Started cloned bot @Andipari364bot
[16-Apr-25 19:06:22 - INFO] - Clone Manager - Started cloned bot @AndreaPlaybot
[16-Apr-25 19:06:23 - INFO] - Clone Manager - Started cloned bot @AntispamfedBot
[16-Apr-25 19:06:24 - INFO] - Clone Manager - Started cloned bot @AXIIVBOT
[16-Apr-25 19:06:25 - INFO] - Clone Manager - Started cloned bot @Elsarobot
[16-Apr-25 19:06:26 - INFO] - Clone Manager - Started cloned bot @QuizPlayBot
[16-Apr-25 19:06:27 - ERROR] - Clone Manager - Error @Savealbot :Telegram says: [401 SESSION_REVOKED] - The authorization has been invalidated, because of the user terminating all sessions (caused by "updates.GetState")
Traceback (most recent call last):
  File "C:\Users\psasw\OneDrive\Desktop\livegram\lgram\__main__.py", line 42, in restart_clones
    await ai.start()
  File "C:\Users\psasw\AppData\Local\Packages\PythonSoftwareFoundation.Python.3.12_qbz5n2kfra8p0\LocalCache\local-packages\Python312\site-packages\pyrogram\methods\utilities\start.py", line 68, in start
    await self.invoke(raw.functions.updates.GetState())
  File "C:\Users\psasw\AppData\Local\Packages\PythonSoftwareFoundation.Python.3.12_qbz5n2kfra8p0\LocalCache\local-packages\Python312\site-packages\pyrogram\methods\advanced\invoke.py", line 79, in invoke
    r = await self.session.invoke(
        ^^^^^^^^^^^^^^^^^^^^^^^^^^
  File "C:\Users\psasw\AppData\Local\Packages\PythonSoftwareFoundation.Python.3.12_qbz5n2kfra8p0\LocalCache\local-packages\Python312\site-packages\pyrogram\session\session.py", line 389, in invoke
    return await self.send(query, timeout=timeout)
           ^^^^^^^^^^^^^^^^^^^^^^^^^^^^^^^^^^^^^^^
  File "C:\Users\psasw\AppData\Local\Packages\PythonSoftwareFoundation.Python.3.12_qbz5n2kfra8p0\LocalCache\local-packages\Python312\site-packages\pyrogram\session\session.py", line 357, in send
    RPCError.raise_it(result, type(data))
  File "C:\Users\psasw\AppData\Local\Packages\PythonSoftwareFoundation.Python.3.12_qbz5n2kfra8p0\LocalCache\local-packages\Python312\site-packages\pyrogram\errors\rpc_error.py", line 91, in raise_it
    raise getattr(
pyrogram.errors.exceptions.unauthorized_401.SessionRevoked: Telegram says: [401 SESSION_REVOKED] - The authorization has been invalidated, because of the user terminating all sessions (caused by "updates.GetState")
[16-Apr-25 19:06:27 - ERROR] - Clone Manager - Error @MissIvoryBot :Telegram says: [401 SESSION_REVOKED] - The authorization has been invalidated, because of the user terminating all sessions (caused by "updates.GetState")
Traceback (most recent call last):
  File "C:\Users\psasw\OneDrive\Desktop\livegram\lgram\__main__.py", line 42, in restart_clones
    await ai.start()
  File "C:\Users\psasw\AppData\Local\Packages\PythonSoftwareFoundation.Python.3.12_qbz5n2kfra8p0\LocalCache\local-packages\Python312\site-packages\pyrogram\methods\utilities\start.py", line 68, in start
    await self.invoke(raw.functions.updates.GetState())
  File "C:\Users\psasw\AppData\Local\Packages\PythonSoftwareFoundation.Python.3.12_qbz5n2kfra8p0\LocalCache\local-packages\Python312\site-packages\pyrogram\methods\advanced\invoke.py", line 79, in invoke
    r = await self.session.invoke(
        ^^^^^^^^^^^^^^^^^^^^^^^^^^
  File "C:\Users\psasw\AppData\Local\Packages\PythonSoftwareFoundation.Python.3.12_qbz5n2kfra8p0\LocalCache\local-packages\Python312\site-packages\pyrogram\session\session.py", line 389, in invoke
    return await self.send(query, timeout=timeout)
           ^^^^^^^^^^^^^^^^^^^^^^^^^^^^^^^^^^^^^^^
  File "C:\Users\psasw\AppData\Local\Packages\PythonSoftwareFoundation.Python.3.12_qbz5n2kfra8p0\LocalCache\local-packages\Python312\site-packages\pyrogram\session\session.py", line 357, in send
    RPCError.raise_it(result, type(data))
  File "C:\Users\psasw\AppData\Local\Packages\PythonSoftwareFoundation.Python.3.12_qbz5n2kfra8p0\LocalCache\local-packages\Python312\site-packages\pyrogram\errors\rpc_error.py", line 91, in raise_it
    raise getattr(
pyrogram.errors.exceptions.unauthorized_401.SessionRevoked: Telegram says: [401 SESSION_REVOKED] - The authorization has been invalidated, because of the user terminating all sessions (caused by "updates.GetState")
[16-Apr-25 19:06:29 - INFO] - Clone Manager - Started cloned bot @IsebellaBot
[16-Apr-25 19:06:30 - INFO] - Clone Manager - Started cloned bot @BESTMEDIA000BOT
[16-Apr-25 19:07:09 - INFO] - root - Stop signal received (SIGINT). Exiting...
[16-Apr-25 19:07:10 - INFO] - root - Stop signal received (SIGINT). Exiting...
[16-Apr-25 19:07:10 - INFO] - root - Stop signal received (SIGINT). Exiting...
[16-Apr-25 19:07:22 - INFO] - lgram.core - Starting Bot...
[16-Apr-25 19:07:22 - INFO] - lgram - Main bot and clone bot management initialized.
[16-Apr-25 19:07:31 - INFO] - lgram.core - Running LgramBot 
[16-Apr-25 19:07:31 - INFO] - lgram modules - Successfully imported all modules.
[16-Apr-25 19:07:31 - INFO] - Clone Manager - Restarting all cloned bots...
[16-Apr-25 19:07:32 - INFO] - Clone Manager - Started cloned bot @ImageGeneratorRoBot
[16-Apr-25 19:07:33 - INFO] - Clone Manager - Started cloned bot @Andipari364bot
[16-Apr-25 19:07:34 - INFO] - Clone Manager - Started cloned bot @AndreaPlaybot
[16-Apr-25 19:07:35 - INFO] - Clone Manager - Started cloned bot @AntispamfedBot
[16-Apr-25 19:07:36 - INFO] - Clone Manager - Started cloned bot @AXIIVBOT
[16-Apr-25 19:07:37 - INFO] - Clone Manager - Started cloned bot @Elsarobot
[16-Apr-25 19:07:38 - INFO] - Clone Manager - Started cloned bot @QuizPlayBot
[16-Apr-25 19:07:39 - ERROR] - Clone Manager - Error @Savealbot :Telegram says: [401 SESSION_REVOKED] - The authorization has been invalidated, because of the user terminating all sessions (caused by "updates.GetState")
Traceback (most recent call last):
  File "C:\Users\psasw\OneDrive\Desktop\livegram\lgram\__main__.py", line 42, in restart_clones
    await ai.start()
  File "C:\Users\psasw\AppData\Local\Packages\PythonSoftwareFoundation.Python.3.12_qbz5n2kfra8p0\LocalCache\local-packages\Python312\site-packages\pyrogram\methods\utilities\start.py", line 68, in start
    await self.invoke(raw.functions.updates.GetState())
  File "C:\Users\psasw\AppData\Local\Packages\PythonSoftwareFoundation.Python.3.12_qbz5n2kfra8p0\LocalCache\local-packages\Python312\site-packages\pyrogram\methods\advanced\invoke.py", line 79, in invoke
    r = await self.session.invoke(
        ^^^^^^^^^^^^^^^^^^^^^^^^^^
  File "C:\Users\psasw\AppData\Local\Packages\PythonSoftwareFoundation.Python.3.12_qbz5n2kfra8p0\LocalCache\local-packages\Python312\site-packages\pyrogram\session\session.py", line 389, in invoke
    return await self.send(query, timeout=timeout)
           ^^^^^^^^^^^^^^^^^^^^^^^^^^^^^^^^^^^^^^^
  File "C:\Users\psasw\AppData\Local\Packages\PythonSoftwareFoundation.Python.3.12_qbz5n2kfra8p0\LocalCache\local-packages\Python312\site-packages\pyrogram\session\session.py", line 357, in send
    RPCError.raise_it(result, type(data))
  File "C:\Users\psasw\AppData\Local\Packages\PythonSoftwareFoundation.Python.3.12_qbz5n2kfra8p0\LocalCache\local-packages\Python312\site-packages\pyrogram\errors\rpc_error.py", line 91, in raise_it
    raise getattr(
pyrogram.errors.exceptions.unauthorized_401.SessionRevoked: Telegram says: [401 SESSION_REVOKED] - The authorization has been invalidated, because of the user terminating all sessions (caused by "updates.GetState")
[16-Apr-25 19:07:40 - ERROR] - Clone Manager - Error @MissIvoryBot :Telegram says: [401 SESSION_REVOKED] - The authorization has been invalidated, because of the user terminating all sessions (caused by "updates.GetState")
Traceback (most recent call last):
  File "C:\Users\psasw\OneDrive\Desktop\livegram\lgram\__main__.py", line 42, in restart_clones
    await ai.start()
  File "C:\Users\psasw\AppData\Local\Packages\PythonSoftwareFoundation.Python.3.12_qbz5n2kfra8p0\LocalCache\local-packages\Python312\site-packages\pyrogram\methods\utilities\start.py", line 68, in start
    await self.invoke(raw.functions.updates.GetState())
  File "C:\Users\psasw\AppData\Local\Packages\PythonSoftwareFoundation.Python.3.12_qbz5n2kfra8p0\LocalCache\local-packages\Python312\site-packages\pyrogram\methods\advanced\invoke.py", line 79, in invoke
    r = await self.session.invoke(
        ^^^^^^^^^^^^^^^^^^^^^^^^^^
  File "C:\Users\psasw\AppData\Local\Packages\PythonSoftwareFoundation.Python.3.12_qbz5n2kfra8p0\LocalCache\local-packages\Python312\site-packages\pyrogram\session\session.py", line 389, in invoke
    return await self.send(query, timeout=timeout)
           ^^^^^^^^^^^^^^^^^^^^^^^^^^^^^^^^^^^^^^^
  File "C:\Users\psasw\AppData\Local\Packages\PythonSoftwareFoundation.Python.3.12_qbz5n2kfra8p0\LocalCache\local-packages\Python312\site-packages\pyrogram\session\session.py", line 357, in send
    RPCError.raise_it(result, type(data))
  File "C:\Users\psasw\AppData\Local\Packages\PythonSoftwareFoundation.Python.3.12_qbz5n2kfra8p0\LocalCache\local-packages\Python312\site-packages\pyrogram\errors\rpc_error.py", line 91, in raise_it
    raise getattr(
pyrogram.errors.exceptions.unauthorized_401.SessionRevoked: Telegram says: [401 SESSION_REVOKED] - The authorization has been invalidated, because of the user terminating all sessions (caused by "updates.GetState")
[16-Apr-25 19:07:41 - INFO] - Clone Manager - Started cloned bot @IsebellaBot
[16-Apr-25 19:07:42 - INFO] - Clone Manager - Started cloned bot @BESTMEDIA000BOT
[16-Apr-25 19:11:54 - INFO] - root - Stop signal received (SIGINT). Exiting...
[16-Apr-25 19:11:55 - INFO] - root - Stop signal received (SIGINT). Exiting...
[16-Apr-25 19:12:04 - INFO] - lgram.core - Starting Bot...
[16-Apr-25 19:12:04 - INFO] - lgram - Main bot and clone bot management initialized.
[16-Apr-25 19:12:13 - INFO] - lgram.core - Running LgramBot 
[16-Apr-25 19:12:14 - INFO] - lgram modules - Successfully imported all modules.
[16-Apr-25 19:12:14 - INFO] - Clone Manager - Restarting all cloned bots...
[16-Apr-25 19:12:15 - INFO] - Clone Manager - Started cloned bot @ImageGeneratorRoBot
[16-Apr-25 19:12:16 - INFO] - Clone Manager - Started cloned bot @Andipari364bot
[16-Apr-25 19:12:17 - INFO] - Clone Manager - Started cloned bot @AndreaPlaybot
[16-Apr-25 19:12:18 - INFO] - Clone Manager - Started cloned bot @AntispamfedBot
[16-Apr-25 19:12:19 - INFO] - Clone Manager - Started cloned bot @AXIIVBOT
[16-Apr-25 19:12:20 - INFO] - Clone Manager - Started cloned bot @Elsarobot
[16-Apr-25 19:12:21 - INFO] - Clone Manager - Started cloned bot @QuizPlayBot
[16-Apr-25 19:12:22 - ERROR] - Clone Manager - Error @Savealbot :Telegram says: [401 SESSION_REVOKED] - The authorization has been invalidated, because of the user terminating all sessions (caused by "updates.GetState")
Traceback (most recent call last):
  File "C:\Users\psasw\OneDrive\Desktop\livegram\lgram\__main__.py", line 42, in restart_clones
    await ai.start()
  File "C:\Users\psasw\AppData\Local\Packages\PythonSoftwareFoundation.Python.3.12_qbz5n2kfra8p0\LocalCache\local-packages\Python312\site-packages\pyrogram\methods\utilities\start.py", line 68, in start
    await self.invoke(raw.functions.updates.GetState())
  File "C:\Users\psasw\AppData\Local\Packages\PythonSoftwareFoundation.Python.3.12_qbz5n2kfra8p0\LocalCache\local-packages\Python312\site-packages\pyrogram\methods\advanced\invoke.py", line 79, in invoke
    r = await self.session.invoke(
        ^^^^^^^^^^^^^^^^^^^^^^^^^^
  File "C:\Users\psasw\AppData\Local\Packages\PythonSoftwareFoundation.Python.3.12_qbz5n2kfra8p0\LocalCache\local-packages\Python312\site-packages\pyrogram\session\session.py", line 389, in invoke
    return await self.send(query, timeout=timeout)
           ^^^^^^^^^^^^^^^^^^^^^^^^^^^^^^^^^^^^^^^
  File "C:\Users\psasw\AppData\Local\Packages\PythonSoftwareFoundation.Python.3.12_qbz5n2kfra8p0\LocalCache\local-packages\Python312\site-packages\pyrogram\session\session.py", line 357, in send
    RPCError.raise_it(result, type(data))
  File "C:\Users\psasw\AppData\Local\Packages\PythonSoftwareFoundation.Python.3.12_qbz5n2kfra8p0\LocalCache\local-packages\Python312\site-packages\pyrogram\errors\rpc_error.py", line 91, in raise_it
    raise getattr(
pyrogram.errors.exceptions.unauthorized_401.SessionRevoked: Telegram says: [401 SESSION_REVOKED] - The authorization has been invalidated, because of the user terminating all sessions (caused by "updates.GetState")
[16-Apr-25 19:12:23 - ERROR] - Clone Manager - Error @MissIvoryBot :Telegram says: [401 SESSION_REVOKED] - The authorization has been invalidated, because of the user terminating all sessions (caused by "updates.GetState")
Traceback (most recent call last):
  File "C:\Users\psasw\OneDrive\Desktop\livegram\lgram\__main__.py", line 42, in restart_clones
    await ai.start()
  File "C:\Users\psasw\AppData\Local\Packages\PythonSoftwareFoundation.Python.3.12_qbz5n2kfra8p0\LocalCache\local-packages\Python312\site-packages\pyrogram\methods\utilities\start.py", line 68, in start
    await self.invoke(raw.functions.updates.GetState())
  File "C:\Users\psasw\AppData\Local\Packages\PythonSoftwareFoundation.Python.3.12_qbz5n2kfra8p0\LocalCache\local-packages\Python312\site-packages\pyrogram\methods\advanced\invoke.py", line 79, in invoke
    r = await self.session.invoke(
        ^^^^^^^^^^^^^^^^^^^^^^^^^^
  File "C:\Users\psasw\AppData\Local\Packages\PythonSoftwareFoundation.Python.3.12_qbz5n2kfra8p0\LocalCache\local-packages\Python312\site-packages\pyrogram\session\session.py", line 389, in invoke
    return await self.send(query, timeout=timeout)
           ^^^^^^^^^^^^^^^^^^^^^^^^^^^^^^^^^^^^^^^
  File "C:\Users\psasw\AppData\Local\Packages\PythonSoftwareFoundation.Python.3.12_qbz5n2kfra8p0\LocalCache\local-packages\Python312\site-packages\pyrogram\session\session.py", line 357, in send
    RPCError.raise_it(result, type(data))
  File "C:\Users\psasw\AppData\Local\Packages\PythonSoftwareFoundation.Python.3.12_qbz5n2kfra8p0\LocalCache\local-packages\Python312\site-packages\pyrogram\errors\rpc_error.py", line 91, in raise_it
    raise getattr(
pyrogram.errors.exceptions.unauthorized_401.SessionRevoked: Telegram says: [401 SESSION_REVOKED] - The authorization has been invalidated, because of the user terminating all sessions (caused by "updates.GetState")
[16-Apr-25 19:12:24 - INFO] - Clone Manager - Started cloned bot @IsebellaBot
[16-Apr-25 19:12:25 - INFO] - Clone Manager - Started cloned bot @BESTMEDIA000BOT
[16-Apr-25 19:22:46 - INFO] - root - Stop signal received (SIGINT). Exiting...
[16-Apr-25 19:22:46 - INFO] - root - Stop signal received (SIGINT). Exiting...
[16-Apr-25 19:22:56 - INFO] - lgram.core - Starting Bot...
[16-Apr-25 19:22:56 - INFO] - lgram - Main bot and clone bot management initialized.
[16-Apr-25 19:23:03 - INFO] - lgram.core - Running LgramBot 
[16-Apr-25 19:23:04 - INFO] - lgram modules - Successfully imported all modules.
[16-Apr-25 19:23:04 - INFO] - Clone Manager - Restarting all cloned bots...
[16-Apr-25 19:23:05 - INFO] - Clone Manager - Started cloned bot @ImageGeneratorRoBot
[16-Apr-25 19:23:06 - INFO] - Clone Manager - Started cloned bot @Andipari364bot
[16-Apr-25 19:23:07 - INFO] - Clone Manager - Started cloned bot @AndreaPlaybot
[16-Apr-25 19:23:08 - INFO] - Clone Manager - Started cloned bot @AntispamfedBot
[16-Apr-25 19:23:09 - INFO] - Clone Manager - Started cloned bot @AXIIVBOT
[16-Apr-25 19:23:10 - INFO] - Clone Manager - Started cloned bot @Elsarobot
[16-Apr-25 19:23:11 - INFO] - Clone Manager - Started cloned bot @QuizPlayBot
[16-Apr-25 19:23:12 - ERROR] - Clone Manager - Error @Savealbot :Telegram says: [401 SESSION_REVOKED] - The authorization has been invalidated, because of the user terminating all sessions (caused by "updates.GetState")
Traceback (most recent call last):
  File "C:\Users\psasw\OneDrive\Desktop\livegram\lgram\__main__.py", line 42, in restart_clones
    await ai.start()
  File "C:\Users\psasw\AppData\Local\Packages\PythonSoftwareFoundation.Python.3.12_qbz5n2kfra8p0\LocalCache\local-packages\Python312\site-packages\pyrogram\methods\utilities\start.py", line 68, in start
    await self.invoke(raw.functions.updates.GetState())
  File "C:\Users\psasw\AppData\Local\Packages\PythonSoftwareFoundation.Python.3.12_qbz5n2kfra8p0\LocalCache\local-packages\Python312\site-packages\pyrogram\methods\advanced\invoke.py", line 79, in invoke
    r = await self.session.invoke(
        ^^^^^^^^^^^^^^^^^^^^^^^^^^
  File "C:\Users\psasw\AppData\Local\Packages\PythonSoftwareFoundation.Python.3.12_qbz5n2kfra8p0\LocalCache\local-packages\Python312\site-packages\pyrogram\session\session.py", line 389, in invoke
    return await self.send(query, timeout=timeout)
           ^^^^^^^^^^^^^^^^^^^^^^^^^^^^^^^^^^^^^^^
  File "C:\Users\psasw\AppData\Local\Packages\PythonSoftwareFoundation.Python.3.12_qbz5n2kfra8p0\LocalCache\local-packages\Python312\site-packages\pyrogram\session\session.py", line 357, in send
    RPCError.raise_it(result, type(data))
  File "C:\Users\psasw\AppData\Local\Packages\PythonSoftwareFoundation.Python.3.12_qbz5n2kfra8p0\LocalCache\local-packages\Python312\site-packages\pyrogram\errors\rpc_error.py", line 91, in raise_it
    raise getattr(
pyrogram.errors.exceptions.unauthorized_401.SessionRevoked: Telegram says: [401 SESSION_REVOKED] - The authorization has been invalidated, because of the user terminating all sessions (caused by "updates.GetState")
[16-Apr-25 19:23:13 - ERROR] - Clone Manager - Error @MissIvoryBot :Telegram says: [401 SESSION_REVOKED] - The authorization has been invalidated, because of the user terminating all sessions (caused by "updates.GetState")
Traceback (most recent call last):
  File "C:\Users\psasw\OneDrive\Desktop\livegram\lgram\__main__.py", line 42, in restart_clones
    await ai.start()
  File "C:\Users\psasw\AppData\Local\Packages\PythonSoftwareFoundation.Python.3.12_qbz5n2kfra8p0\LocalCache\local-packages\Python312\site-packages\pyrogram\methods\utilities\start.py", line 68, in start
    await self.invoke(raw.functions.updates.GetState())
  File "C:\Users\psasw\AppData\Local\Packages\PythonSoftwareFoundation.Python.3.12_qbz5n2kfra8p0\LocalCache\local-packages\Python312\site-packages\pyrogram\methods\advanced\invoke.py", line 79, in invoke
    r = await self.session.invoke(
        ^^^^^^^^^^^^^^^^^^^^^^^^^^
  File "C:\Users\psasw\AppData\Local\Packages\PythonSoftwareFoundation.Python.3.12_qbz5n2kfra8p0\LocalCache\local-packages\Python312\site-packages\pyrogram\session\session.py", line 389, in invoke
    return await self.send(query, timeout=timeout)
           ^^^^^^^^^^^^^^^^^^^^^^^^^^^^^^^^^^^^^^^
  File "C:\Users\psasw\AppData\Local\Packages\PythonSoftwareFoundation.Python.3.12_qbz5n2kfra8p0\LocalCache\local-packages\Python312\site-packages\pyrogram\session\session.py", line 357, in send
    RPCError.raise_it(result, type(data))
  File "C:\Users\psasw\AppData\Local\Packages\PythonSoftwareFoundation.Python.3.12_qbz5n2kfra8p0\LocalCache\local-packages\Python312\site-packages\pyrogram\errors\rpc_error.py", line 91, in raise_it
    raise getattr(
pyrogram.errors.exceptions.unauthorized_401.SessionRevoked: Telegram says: [401 SESSION_REVOKED] - The authorization has been invalidated, because of the user terminating all sessions (caused by "updates.GetState")
[16-Apr-25 19:23:14 - INFO] - Clone Manager - Started cloned bot @IsebellaBot
[16-Apr-25 19:23:15 - INFO] - Clone Manager - Started cloned bot @BESTMEDIA000BOT
[16-Apr-25 19:23:46 - ERROR] - pyrogram.dispatcher - argument of type 'int' is not iterable
Traceback (most recent call last):
  File "C:\Users\psasw\AppData\Local\Packages\PythonSoftwareFoundation.Python.3.12_qbz5n2kfra8p0\LocalCache\local-packages\Python312\site-packages\pyrogram\dispatcher.py", line 240, in handler_worker
    await handler.callback(self.client, *args)
  File "C:\Users\psasw\OneDrive\Desktop\livegram\lgram\functions\wetdreams.py", line 230, in main_broadcast_handler
    if message.from_user.id not in SUDO_USERS:
       ^^^^^^^^^^^^^^^^^^^^^^^^^^^^^^^^^^^^^^
TypeError: argument of type 'int' is not iterable
[16-Apr-25 19:26:09 - INFO] - root - Stop signal received (SIGINT). Exiting...
[16-Apr-25 19:26:09 - INFO] - root - Stop signal received (SIGINT). Exiting...
[16-Apr-25 19:26:17 - INFO] - lgram.core - Starting Bot...
[16-Apr-25 19:26:17 - INFO] - lgram - Main bot and clone bot management initialized.
[16-Apr-25 19:26:26 - INFO] - lgram.core - Running LgramBot 
[16-Apr-25 19:26:26 - INFO] - lgram modules - Successfully imported all modules.
[16-Apr-25 19:26:26 - INFO] - Clone Manager - Restarting all cloned bots...
[16-Apr-25 19:26:27 - INFO] - Clone Manager - Started cloned bot @ImageGeneratorRoBot
[16-Apr-25 19:26:28 - INFO] - Clone Manager - Started cloned bot @Andipari364bot
[16-Apr-25 19:26:30 - INFO] - Clone Manager - Started cloned bot @AndreaPlaybot
[16-Apr-25 19:26:31 - INFO] - Clone Manager - Started cloned bot @AntispamfedBot
[16-Apr-25 19:26:32 - INFO] - Clone Manager - Started cloned bot @AXIIVBOT
[16-Apr-25 19:26:32 - INFO] - Clone Manager - Started cloned bot @Elsarobot
[16-Apr-25 19:26:33 - INFO] - Clone Manager - Started cloned bot @QuizPlayBot
[16-Apr-25 19:26:34 - ERROR] - Clone Manager - Error @Savealbot :Telegram says: [401 SESSION_REVOKED] - The authorization has been invalidated, because of the user terminating all sessions (caused by "updates.GetState")
Traceback (most recent call last):
  File "C:\Users\psasw\OneDrive\Desktop\livegram\lgram\__main__.py", line 42, in restart_clones
    await ai.start()
  File "C:\Users\psasw\AppData\Local\Packages\PythonSoftwareFoundation.Python.3.12_qbz5n2kfra8p0\LocalCache\local-packages\Python312\site-packages\pyrogram\methods\utilities\start.py", line 68, in start
    await self.invoke(raw.functions.updates.GetState())
  File "C:\Users\psasw\AppData\Local\Packages\PythonSoftwareFoundation.Python.3.12_qbz5n2kfra8p0\LocalCache\local-packages\Python312\site-packages\pyrogram\methods\advanced\invoke.py", line 79, in invoke
    r = await self.session.invoke(
        ^^^^^^^^^^^^^^^^^^^^^^^^^^
  File "C:\Users\psasw\AppData\Local\Packages\PythonSoftwareFoundation.Python.3.12_qbz5n2kfra8p0\LocalCache\local-packages\Python312\site-packages\pyrogram\session\session.py", line 389, in invoke
    return await self.send(query, timeout=timeout)
           ^^^^^^^^^^^^^^^^^^^^^^^^^^^^^^^^^^^^^^^
  File "C:\Users\psasw\AppData\Local\Packages\PythonSoftwareFoundation.Python.3.12_qbz5n2kfra8p0\LocalCache\local-packages\Python312\site-packages\pyrogram\session\session.py", line 357, in send
    RPCError.raise_it(result, type(data))
  File "C:\Users\psasw\AppData\Local\Packages\PythonSoftwareFoundation.Python.3.12_qbz5n2kfra8p0\LocalCache\local-packages\Python312\site-packages\pyrogram\errors\rpc_error.py", line 91, in raise_it
    raise getattr(
pyrogram.errors.exceptions.unauthorized_401.SessionRevoked: Telegram says: [401 SESSION_REVOKED] - The authorization has been invalidated, because of the user terminating all sessions (caused by "updates.GetState")
[16-Apr-25 19:26:35 - ERROR] - Clone Manager - Error @MissIvoryBot :Telegram says: [401 SESSION_REVOKED] - The authorization has been invalidated, because of the user terminating all sessions (caused by "updates.GetState")
Traceback (most recent call last):
  File "C:\Users\psasw\OneDrive\Desktop\livegram\lgram\__main__.py", line 42, in restart_clones
    await ai.start()
  File "C:\Users\psasw\AppData\Local\Packages\PythonSoftwareFoundation.Python.3.12_qbz5n2kfra8p0\LocalCache\local-packages\Python312\site-packages\pyrogram\methods\utilities\start.py", line 68, in start
    await self.invoke(raw.functions.updates.GetState())
  File "C:\Users\psasw\AppData\Local\Packages\PythonSoftwareFoundation.Python.3.12_qbz5n2kfra8p0\LocalCache\local-packages\Python312\site-packages\pyrogram\methods\advanced\invoke.py", line 79, in invoke
    r = await self.session.invoke(
        ^^^^^^^^^^^^^^^^^^^^^^^^^^
  File "C:\Users\psasw\AppData\Local\Packages\PythonSoftwareFoundation.Python.3.12_qbz5n2kfra8p0\LocalCache\local-packages\Python312\site-packages\pyrogram\session\session.py", line 389, in invoke
    return await self.send(query, timeout=timeout)
           ^^^^^^^^^^^^^^^^^^^^^^^^^^^^^^^^^^^^^^^
  File "C:\Users\psasw\AppData\Local\Packages\PythonSoftwareFoundation.Python.3.12_qbz5n2kfra8p0\LocalCache\local-packages\Python312\site-packages\pyrogram\session\session.py", line 357, in send
    RPCError.raise_it(result, type(data))
  File "C:\Users\psasw\AppData\Local\Packages\PythonSoftwareFoundation.Python.3.12_qbz5n2kfra8p0\LocalCache\local-packages\Python312\site-packages\pyrogram\errors\rpc_error.py", line 91, in raise_it
    raise getattr(
pyrogram.errors.exceptions.unauthorized_401.SessionRevoked: Telegram says: [401 SESSION_REVOKED] - The authorization has been invalidated, because of the user terminating all sessions (caused by "updates.GetState")
[16-Apr-25 19:26:36 - INFO] - Clone Manager - Started cloned bot @IsebellaBot
[16-Apr-25 19:26:38 - INFO] - Clone Manager - Started cloned bot @BESTMEDIA000BOT
[16-Apr-25 19:28:32 - INFO] - root - Stop signal received (SIGINT). Exiting...
[16-Apr-25 19:28:32 - INFO] - root - Stop signal received (SIGINT). Exiting...
[16-Apr-25 19:28:33 - INFO] - root - Stop signal received (SIGINT). Exiting...
[16-Apr-25 19:28:46 - INFO] - lgram.core - Starting Bot...
[16-Apr-25 19:28:46 - INFO] - lgram - Main bot and clone bot management initialized.
[16-Apr-25 19:28:55 - INFO] - lgram.core - Running LgramBot 
[16-Apr-25 19:28:55 - INFO] - lgram modules - Successfully imported all modules.
[16-Apr-25 19:28:55 - INFO] - Clone Manager - Restarting all cloned bots...
[16-Apr-25 19:28:57 - INFO] - Clone Manager - Started cloned bot @ImageGeneratorRoBot
[16-Apr-25 19:28:57 - INFO] - Clone Manager - Started cloned bot @Andipari364bot
[16-Apr-25 19:28:58 - INFO] - Clone Manager - Started cloned bot @AndreaPlaybot
[16-Apr-25 19:28:59 - INFO] - Clone Manager - Started cloned bot @AntispamfedBot
[16-Apr-25 19:29:00 - INFO] - Clone Manager - Started cloned bot @AXIIVBOT
[16-Apr-25 19:29:01 - INFO] - Clone Manager - Started cloned bot @Elsarobot
[16-Apr-25 19:29:02 - INFO] - Clone Manager - Started cloned bot @QuizPlayBot
[16-Apr-25 19:29:03 - ERROR] - Clone Manager - Error @Savealbot :Telegram says: [401 SESSION_REVOKED] - The authorization has been invalidated, because of the user terminating all sessions (caused by "updates.GetState")
Traceback (most recent call last):
  File "C:\Users\psasw\OneDrive\Desktop\livegram\lgram\__main__.py", line 42, in restart_clones
    await ai.start()
  File "C:\Users\psasw\AppData\Local\Packages\PythonSoftwareFoundation.Python.3.12_qbz5n2kfra8p0\LocalCache\local-packages\Python312\site-packages\pyrogram\methods\utilities\start.py", line 68, in start
    await self.invoke(raw.functions.updates.GetState())
  File "C:\Users\psasw\AppData\Local\Packages\PythonSoftwareFoundation.Python.3.12_qbz5n2kfra8p0\LocalCache\local-packages\Python312\site-packages\pyrogram\methods\advanced\invoke.py", line 79, in invoke
    r = await self.session.invoke(
        ^^^^^^^^^^^^^^^^^^^^^^^^^^
  File "C:\Users\psasw\AppData\Local\Packages\PythonSoftwareFoundation.Python.3.12_qbz5n2kfra8p0\LocalCache\local-packages\Python312\site-packages\pyrogram\session\session.py", line 389, in invoke
    return await self.send(query, timeout=timeout)
           ^^^^^^^^^^^^^^^^^^^^^^^^^^^^^^^^^^^^^^^
  File "C:\Users\psasw\AppData\Local\Packages\PythonSoftwareFoundation.Python.3.12_qbz5n2kfra8p0\LocalCache\local-packages\Python312\site-packages\pyrogram\session\session.py", line 357, in send
    RPCError.raise_it(result, type(data))
  File "C:\Users\psasw\AppData\Local\Packages\PythonSoftwareFoundation.Python.3.12_qbz5n2kfra8p0\LocalCache\local-packages\Python312\site-packages\pyrogram\errors\rpc_error.py", line 91, in raise_it
    raise getattr(
pyrogram.errors.exceptions.unauthorized_401.SessionRevoked: Telegram says: [401 SESSION_REVOKED] - The authorization has been invalidated, because of the user terminating all sessions (caused by "updates.GetState")
[16-Apr-25 19:29:04 - ERROR] - Clone Manager - Error @MissIvoryBot :Telegram says: [401 SESSION_REVOKED] - The authorization has been invalidated, because of the user terminating all sessions (caused by "updates.GetState")
Traceback (most recent call last):
  File "C:\Users\psasw\OneDrive\Desktop\livegram\lgram\__main__.py", line 42, in restart_clones
    await ai.start()
  File "C:\Users\psasw\AppData\Local\Packages\PythonSoftwareFoundation.Python.3.12_qbz5n2kfra8p0\LocalCache\local-packages\Python312\site-packages\pyrogram\methods\utilities\start.py", line 68, in start
    await self.invoke(raw.functions.updates.GetState())
  File "C:\Users\psasw\AppData\Local\Packages\PythonSoftwareFoundation.Python.3.12_qbz5n2kfra8p0\LocalCache\local-packages\Python312\site-packages\pyrogram\methods\advanced\invoke.py", line 79, in invoke
    r = await self.session.invoke(
        ^^^^^^^^^^^^^^^^^^^^^^^^^^
  File "C:\Users\psasw\AppData\Local\Packages\PythonSoftwareFoundation.Python.3.12_qbz5n2kfra8p0\LocalCache\local-packages\Python312\site-packages\pyrogram\session\session.py", line 389, in invoke
    return await self.send(query, timeout=timeout)
           ^^^^^^^^^^^^^^^^^^^^^^^^^^^^^^^^^^^^^^^
  File "C:\Users\psasw\AppData\Local\Packages\PythonSoftwareFoundation.Python.3.12_qbz5n2kfra8p0\LocalCache\local-packages\Python312\site-packages\pyrogram\session\session.py", line 357, in send
    RPCError.raise_it(result, type(data))
  File "C:\Users\psasw\AppData\Local\Packages\PythonSoftwareFoundation.Python.3.12_qbz5n2kfra8p0\LocalCache\local-packages\Python312\site-packages\pyrogram\errors\rpc_error.py", line 91, in raise_it
    raise getattr(
pyrogram.errors.exceptions.unauthorized_401.SessionRevoked: Telegram says: [401 SESSION_REVOKED] - The authorization has been invalidated, because of the user terminating all sessions (caused by "updates.GetState")
[16-Apr-25 19:29:05 - INFO] - Clone Manager - Started cloned bot @IsebellaBot
[16-Apr-25 19:29:06 - INFO] - Clone Manager - Started cloned bot @BESTMEDIA000BOT
[16-Apr-25 19:32:38 - INFO] - root - Stop signal received (SIGINT). Exiting...
[16-Apr-25 19:32:39 - INFO] - root - Stop signal received (SIGINT). Exiting...
[16-Apr-25 19:32:39 - INFO] - root - Stop signal received (SIGINT). Exiting...
